Workbook

Sheet Behaviourability
A1: # | B1: Tasks | C1: Decision Making | D1: Self-Management | E1: Communication | F1: Engagement
A2: 1 | B2: Consultare gli orari ufficiali | C2: PC | D2: SE
A3: 2 | B3: Controllare la disponibilità dei biglietti ed i loro prezzi | C3: PC
A4: 3 | B4: Consultare le informazioni generali | D4: SE
A5: 4 | B5: Ottenere informazioni sull'accessibilità del sito | C5: SE | D5: PC, K&S
A6: 5 | B6: Traduzione in tempo reale | D6: PC | E6: SE | F6: MOT
A7: 6 | B7: Creazione e condivisione di itinerari | D7: PC | F7: MOT
A8: 7 | B8: Visualizzazione dei badge distintivi ottenuti e del livello di turista | F8: MOT
A9: 8 | B9: Filtrare siti per preferenze | D9: PC, MOT
A10: 9 | B10: Approfondire informazioni | F10: MOT
A11: 10 | B11: Consiglire una visita a un sito | E11: K&S | F11: MOT
B13: Legenda
B14: SE = Self-Efficacy
B15: K&S = Knowledge & Skills
B16: PC = Personal Control
B17: MOT = Motivation

Sheet Tabella dei risultati
A1: # | B1: Tasks | C1: ASE | D1: AKS | E1: APC | F1: AMOT
A2: 1 | B2: Consultare gli orari ufficiali | C2: ='Media delle risposte'!C2 -> 4.6 | D2: - | E2: ='Media delle risposte'!C4 -> 4.2 | F2: -
A3: 2 | B3: Controllare la disponibilità dei biglietti ed i loro prezzi | C3: - | D3: - | E3: ='Media delle risposte'!C6 -> 4.4 | F3: -
A4: 3 | B4: Consultare le informazioni generali | C4: ='Media delle risposte'!C8 -> 4.2 | D4: - | E4: - | F4: -
A5: 4 | B5: Ottenere informazioni sull'accessibilità del sito | C5: ='Media delle risposte'!C10 -> 4.4 | D5: ='Media delle risposte'!C12 -> 3.9 | E5: ='Media delle risposte'!C14 -> 4.8 | F5: -
A6: 5 | B6: Traduzione in tempo reale | C6: ='Media delle risposte'!C16 -> 3.5 | D6: - | E6: ='Media delle risposte'!C18 -> 3.9 | F6: ='Media delle risposte'!C20 -> 3.9
A7: 6 | B7: Creazione e condivisione di itinerari | C7: - | D7: - | E7: ='Media delle risposte'!C22 -> 4.4 | F7: ='Media delle risposte'!C24 -> 4.6
A8: 7 | B8: Visualizzazione dei badge distintivi ottenuti e del livello di turista | C8: - | D8: - | E8: - | F8: ='Media delle risposte'!C26 -> 4.1
A9: 8 | B9: Filtrare siti per preferenze | C9: - | D9: - | E9: ='Media delle risposte'!C28 -> 3.9 | F9: ='Media delle risposte'!C30 -> 4
A10: 9 | B10: Approfondire informazioni | C10: - | D10: - | E10: - | F10: ='Media delle risposte'!C32 -> 4.5
A11: 10 | B11: Consiglire una visita a un sito | C11: - | D11: ='Media delle risposte'!C34 -> 4 | E11: - | F11: ='Media delle risposte'!C36 -> 4.2
B13: Legenda
B14: ASE = Average Self-Efficacy
B15: AKS = Average Knowledge & Skills
B16: APC = Average Personal Control
B17: AMOT = Average Motivation

Sheet Media delle risposte
B1: Self Efficacy | C1: Media
A2: T1_SE1 | B2: Quanto hai trovato chiaro e immediato reperire le informazioni pratiche di un punto di interesse (orari di apertura, prezzi o modalità di acquisto biglietti)? | C2: =AVERAGE('Questionario #1'!H2,'Questionario #2'!H2,'Questionario #3'!H2,'Questionario #4'!H2,'Questionario #5'!H2,'Questionario #6'!H2,'Questionario #7'!H2,'Questionario #8'!H2,'Questionario #9'!H2,'Questionario #10'!H2) -> 4.6
B3: Personal Control
A4: T1_PC1 | B4: Quanto hai trovato facile pianificare e concordare le proprie visite consultando gli orari forniti dal sistema? | C4: =AVERAGE('Questionario #1'!H4,'Questionario #2'!H4,'Questionario #3'!H4,'Questionario #4'!H4,'Questionario #5'!H4,'Questionario #6'!H4,'Questionario #7'!H4,'Questionario #8'!H4,'Questionario #9'!H4,'Questionario #10'!H4) -> 4.2
B5: Personal Control | C5: Valore
A6: T2_PC1 | B6: Quanto hai trovato facile ottenere informazioni sui prezzi dei biglietti e sulle biglietterie ufficiali? | C6: =AVERAGE('Questionario #1'!H6,'Questionario #2'!H6,'Questionario #3'!H6,'Questionario #4'!H6,'Questionario #5'!H6,'Questionario #6'!H6,'Questionario #7'!H6,'Questionario #8'!H6,'Questionario #9'!H6,'Questionario #10'!H6) -> 4.4
B7: Self Efficacy | C7: Valore
A8: T3_SE1 | B8: Quanto sono risultate chiare, complete e leggibili le informazioni generali e le descrizioni dei luoghi proposti? | C8: =AVERAGE('Questionario #1'!H8,'Questionario #2'!H8,'Questionario #3'!H8,'Questionario #4'!H8,'Questionario #5'!H8,'Questionario #6'!H8,'Questionario #7'!H8,'Questionario #8'!H8,'Questionario #9'!H8,'Questionario #10'!H8) -> 4.2
B9: Self Efficacy | C9: Valore
A10: T4_SE1 | B10: Le informazioni sull'accessibilità dei siti (es. barriere architettoniche, percorsi dedicati) ti hanno permesso di organizzare la visita in modo più consapevole e agevole? | C10: =AVERAGE('Questionario #1'!H10,'Questionario #2'!H10,'Questionario #3'!H10,'Questionario #4'!H10,'Questionario #5'!H10,'Questionario #6'!H10,'Questionario #7'!H10,'Questionario #8'!H10,'Questionario #9'!H10,'Questionario #10'!H10) -> 4.4
B11: Knowledge&Skills
A12: T4_KS1 | B12: Le informazioni sull'accessibilità dei siti (es. barriere architettoniche, percorsi dedicati) sono sufficienti per chi è portatore di handicap? | C12: =AVERAGE('Questionario #1'!H12,'Questionario #2'!H12,'Questionario #3'!H12,'Questionario #4'!H12,'Questionario #5'!H12,'Questionario #6'!H12,'Questionario #7'!H12,'Questionario #8'!H12,'Questionario #9'!H12,'Questionario #10'!H12) -> 3.9
B13: Personal Control
A14: T4_PC1 | B14: Le informazioni sull'accessibilità dei siti (es. barriere architettoniche, percorsi dedicati) hanno influenzato positivamente le tue decisioni sulle visite ai punti di interesse? | C14: =AVERAGE('Questionario #1'!H14,'Questionario #2'!H14,'Questionario #3'!H14,'Questionario #4'!H14,'Questionario #5'!H14,'Questionario #6'!H14,'Questionario #7'!H14,'Questionario #8'!H14,'Questionario #9'!H14,'Questionario #10'!H14) -> 4.8
B15: Self Efficacy | C15: Valore
A16: T5_SE1 | B16: Quanto sono chiare e complete le informazioni tradotte nella propria lingua? | C16: =AVERAGE('Questionario #1'!H16,'Questionario #2'!H16,'Questionario #3'!H16,'Questionario #4'!H16,'Questionario #5'!H16,'Questionario #6'!H16,'Questionario #7'!H16,'Questionario #8'!H16,'Questionario #9'!H16,'Questionario #10'!H16) -> 3.5
B17: Personal Control
A18: T5_PC1 | B18: Le traduzioni disponibili hanno influenzato positivamente le tue decisioni sulle visite ai punti di interesse? | C18: =AVERAGE('Questionario #1'!H18,'Questionario #2'!H18,'Questionario #3'!H18,'Questionario #4'!H18,'Questionario #5'!H18,'Questionario #6'!H18,'Questionario #7'!H18,'Questionario #8'!H18,'Questionario #9'!H18,'Questionario #10'!H18) -> 3.9
B19: Motivation
A20: T5_MOT1 | B20: Conoscere le curiosità di un punto di interesse tradotto nella propria lingua ti ha motivat* a visitarlo? | C20: =AVERAGE('Questionario #1'!H20,'Questionario #2'!H20,'Questionario #3'!H20,'Questionario #4'!H20,'Questionario #5'!H20,'Questionario #6'!H20,'Questionario #7'!H20,'Questionario #8'!H20,'Questionario #9'!H20,'Questionario #10'!H20) -> 3.9
B21: Personal Control | C21: Valore
A22: T6_PC1 | B22: Quanto ti è sembrato semplice e lineare il processo di creazione di un itinerario su misura per le tue esigenze? | C22: =AVERAGE('Questionario #1'!H22,'Questionario #2'!H22,'Questionario #3'!H22,'Questionario #4'!H22,'Questionario #5'!H22,'Questionario #6'!H22,'Questionario #7'!H22,'Questionario #8'!H22,'Questionario #9'!H22,'Questionario #10'!H22) -> 4.4
B23: Motivation
A24: T6_MOT1 | B24: Conoscere un itinerario adatto al proprio viaggio ha influenzato positivamente la pianificazione del proprio viaggio? | C24: =AVERAGE('Questionario #1'!H24,'Questionario #2'!H24,'Questionario #3'!H24,'Questionario #4'!H24,'Questionario #5'!H24,'Questionario #6'!H24,'Questionario #7'!H24,'Questionario #8'!H24,'Questionario #9'!H24,'Questionario #10'!H24) -> 4.6
B25: Motivation | C25: Valore
A26: T7_MOT1 | B26: I badge e il sistema di gamification ti ha motivat*? | C26: =AVERAGE('Questionario #1'!H26,'Questionario #2'!H26,'Questionario #3'!H26,'Questionario #4'!H26,'Questionario #5'!H26,'Questionario #6'!H26,'Questionario #7'!H26,'Questionario #8'!H26,'Questionario #9'!H26,'Questionario #10'!H26) -> 4.1
B27: Personal Control | C27: Valore
A28: T8_SE1 | B28: In che misura le categorie e i filtri di ricerca proposti dal sistema rispecchiano le tue reali preferenze di viaggio e culturali? | C28: =AVERAGE('Questionario #1'!H28,'Questionario #2'!H28,'Questionario #3'!H28,'Questionario #4'!H28,'Questionario #5'!H28,'Questionario #6'!H28,'Questionario #7'!H28,'Questionario #8'!H28,'Questionario #9'!H28,'Questionario #10'!H28) -> 3.9
B29: Motivation
A30: T8_MOT1 | B30: In che misura le categorie e i filtri di ricerca proposti dal sistema ti hanno motivat*? | C30: =AVERAGE('Questionario #1'!H30,'Questionario #2'!H30,'Questionario #3'!H30,'Questionario #4'!H30,'Questionario #5'!H30,'Questionario #6'!H30,'Questionario #7'!H30,'Questionario #8'!H30,'Questionario #9'!H30,'Questionario #10'!H30) -> 4
B31: Motivation | C31: Valore
A32: T9_MOT1 | B32: Quanto ritieni che il sistema ti abbia aiutato a scoprire curiosità o approfondimenti storici/culturali sul territorio che prima non conoscevi? | C32: =AVERAGE('Questionario #1'!H32,'Questionario #2'!H32,'Questionario #3'!H32,'Questionario #4'!H32,'Questionario #5'!H32,'Questionario #6'!H32,'Questionario #7'!H32,'Questionario #8'!H32,'Questionario #9'!H32,'Questionario #10'!H32) -> 4.5
B33: Knowledge&Skills | C33: Valore
A34: T10_KS1 | B34: Al termine dell'utilizzo del sistema, ti senti sufficientemente informato/a da poterti orientare nel territorio o consigliare la visita a qualcun altro? | C34: =AVERAGE('Questionario #1'!H34,'Questionario #2'!H34,'Questionario #3'!H34,'Questionario #4'!H34,'Questionario #5'!H34,'Questionario #6'!H34,'Questionario #7'!H34,'Questionario #8'!H34,'Questionario #9'!H34,'Questionario #10'!H34) -> 4
B35: Motivation
A36: T10_MOT1 | B36: In che modo il suggerimento di un itinerario da altri utenti ha influenzato le tue visite? | C36: =AVERAGE('Questionario #1'!H36,'Questionario #2'!H36,'Questionario #3'!H36,'Questionario #4'!H36,'Questionario #5'!H36,'Questionario #6'!H36,'Questionario #7'!H36,'Questionario #8'!H36,'Questionario #9'!H36,'Questionario #10'!H36) -> 4.2

Sheet Questionario base
B1: Self Efficacy | C1: Scarso | D1: Sufficiente | E1: Buono | F1: Molto Buono | G1: Eccellente | H1: Valore
A2: T1_SE1 | B2: Quanto hai trovato chiaro e immediato reperire le informazioni pratiche di un punto di interesse (orari di apertura, prezzi o modalità di acquisto biglietti)? | H2: =IF(C2="X",1)+IF(D2="X",2)+IF(E2="X",3)+IF(F2="X",4)+IF(G2="X",5) -> 0
B3: Personal Control
A4: T1_PC1 | B4: Quanto hai trovato facile pianificare e concordare le proprie visite consultando gli orari forniti dal sistema? | H4: =IF(C4="X",1)+IF(D4="X",2)+IF(E4="X",3)+IF(F4="X",4)+IF(G4="X",5) -> 0
B5: Personal Control | C5: Scarso | D5: Sufficiente | E5: Buono | F5: Molto Buono | G5: Eccellente | H5: Valore
A6: T2_PC1 | B6: Quanto hai trovato facile ottenere informazioni sui prezzi dei biglietti e sulle biglietterie ufficiali? | H6: =IF(C6="X",1)+IF(D6="X",2)+IF(E6="X",3)+IF(F6="X",4)+IF(G6="X",5) -> 0
B7: Self Efficacy | C7: Scarso | D7: Sufficiente | E7: Buono | F7: Molto Buono | G7: Eccellente | H7: Valore
A8: T3_SE1 | B8: Quanto sono risultate chiare, complete e leggibili le informazioni generali e le descrizioni dei luoghi proposti? | H8: =IF(C8="X",1)+IF(D8="X",2)+IF(E8="X",3)+IF(F8="X",4)+IF(G8="X",5) -> 0
B9: Self Efficacy | C9: Scarso | D9: Sufficiente | E9: Buono | F9: Molto Buono | G9: Eccellente | H9: Valore
A10: T4_SE1 | B10: Le informazioni sull'accessibilità dei siti (es. barriere architettoniche, percorsi dedicati) ti hanno permesso di organizzare la visita in modo più consapevole e agevole? | H10: =IF(C10="X",1)+IF(D10="X",2)+IF(E10="X",3)+IF(F10="X",4)+IF(G10="X",5) -> 0
B11: Knowledge&Skills
A12: T4_KS1 | B12: Le informazioni sull'accessibilità dei siti (es. barriere architettoniche, percorsi dedicati) sono sufficienti per chi è portatore di handicap? | H12: =IF(C12="X",1)+IF(D12="X",2)+IF(E12="X",3)+IF(F12="X",4)+IF(G12="X",5) -> 0
B13: Personal Control
A14: T4_PC1 | B14: Le informazioni sull'accessibilità dei siti (es. barriere architettoniche, percorsi dedicati) hanno influenzato positivamente le tue decisioni sulle visite ai punti di interesse? | H14: =IF(C14="X",1)+IF(D14="X",2)+IF(E14="X",3)+IF(F14="X",4)+IF(G14="X",5) -> 0
B15: Self Efficacy | C15: Scarso | D15: Sufficiente | E15: Buono | F15: Molto Buono | G15: Eccellente | H15: Valore
A16: T5_SE1 | B16: Quanto sono chiare e complete le informazioni tradotte nella propria lingua? | H16: =IF(C16="X",1)+IF(D16="X",2)+IF(E16="X",3)+IF(F16="X",4)+IF(G16="X",5) -> 0
B17: Personal Control
A18: T5_PC1 | B18: Le traduzioni disponibili hanno influenzato positivamente le tue decisioni sulle visite ai punti di interesse? | H18: =IF(C18="X",1)+IF(D18="X",2)+IF(E18="X",3)+IF(F18="X",4)+IF(G18="X",5) -> 0
B19: Motivation
A20: T5_MOT1 | B20: Conoscere le curiosità di un punto di interesse tradotto nella propria lingua ti ha motivat* a visitarlo? | H20: =IF(C20="X",1)+IF(D20="X",2)+IF(E20="X",3)+IF(F20="X",4)+IF(G20="X",5) -> 0
B21: Personal Control | C21: Scarso | D21: Sufficiente | E21: Buono | F21: Molto Buono | G21: Eccellente | H21: Valore
A22: T6_PC1 | B22: Quanto ti è sembrato semplice e lineare il processo di creazione di un itinerario su misura per le tue esigenze? | H22: =IF(C22="X",1)+IF(D22="X",2)+IF(E22="X",3)+IF(F22="X",4)+IF(G22="X",5) -> 0
B23: Motivation
A24: T6_MOT1 | B24: Conoscere un itinerario adatto al proprio viaggio ha influenzato positivamente la pianificazione del proprio viaggio? | H24: =IF(C24="X",1)+IF(D24="X",2)+IF(E24="X",3)+IF(F24="X",4)+IF(G24="X",5) -> 0
B25: Motivation | C25: Scarso | D25: Sufficiente | E25: Buono | F25: Molto Buono | G25: Eccellente | H25: Valore
A26: T7_MOT1 | B26: I badge e il sistema di gamification ti ha motivat*? | H26: =IF(C26="X",1)+IF(D26="X",2)+IF(E26="X",3)+IF(F26="X",4)+IF(G26="X",5) -> 0
B27: Personal Control | C27: Scarso | D27: Sufficiente | E27: Buono | F27: Molto Buono | G27: Eccellente | H27: Valore
A28: T8_SE1 | B28: In che misura le categorie e i filtri di ricerca proposti dal sistema rispecchiano le tue reali preferenze di viaggio e culturali? | H28: =IF(C28="X",1)+IF(D28="X",2)+IF(E28="X",3)+IF(F28="X",4)+IF(G28="X",5) -> 0
B29: Motivation
A30: T8_MOT1 | B30: In che misura le categorie e i filtri di ricerca proposti dal sistema ti hanno motivat*? | H30: =IF(C30="X",1)+IF(D30="X",2)+IF(E30="X",3)+IF(F30="X",4)+IF(G30="X",5) -> 0
B31: Motivation | C31: Scarso | D31: Sufficiente | E31: Buono | F31: Molto Buono | G31: Eccellente | H31: Valore
A32: T9_MOT1 | B32: Quanto ritieni che il sistema ti abbia aiutato a scoprire curiosità o approfondimenti storici/culturali sul territorio che prima non conoscevi? | H32: =IF(C32="X",1)+IF(D32="X",2)+IF(E32="X",3)+IF(F32="X",4)+IF(G32="X",5) -> 0
B33: Knowledge&Skills | C33: Scarso | D33: Sufficiente | E33: Buono | F33: Molto Buono | G33: Eccellente | H33: Valore
A34: T10_KS1 | B34: Al termine dell'utilizzo del sistema, ti senti sufficientemente informato/a da poterti orientare nel territorio o consigliare la visita a qualcun altro? | H34: =IF(C34="X",1)+IF(D34="X",2)+IF(E34="X",3)+IF(F34="X",4)+IF(G34="X",5) -> 0
B35: Motivation
A36: T10_MOT1 | B36: In che modo il suggerimento di un itinerario da altri utenti ha influenzato le tue visite? | H36: =IF(C36="X",1)+IF(D36="X",2)+IF(E36="X",3)+IF(F36="X",4)+IF(G36="X",5) -> 0

Sheet Questionario #1
B1: Self Efficacy | C1: Scarso | D1: Sufficiente | E1: Buono | F1: Molto Buono | G1: Eccellente | H1: Valore
A2: T1_SE1 | B2: Quanto hai trovato chiaro e immediato reperire le informazioni pratiche di un punto di interesse (orari di apertura, prezzi o modalità di acquisto biglietti)? | G2: x | H2: =IF(C2="X",1)+IF(D2="X",2)+IF(E2="X",3)+IF(F2="X",4)+IF(G2="X",5) -> 5
B3: Personal Control
A4: T1_PC1 | B4: Quanto hai trovato facile pianificare e concordare le proprie visite consultando gli orari forniti dal sistema? | F4: x | H4: =IF(C4="X",1)+IF(D4="X",2)+IF(E4="X",3)+IF(F4="X",4)+IF(G4="X",5) -> 4
B5: Personal Control | C5: Scarso | D5: Sufficiente | E5: Buono | F5: Molto Buono | G5: Eccellente | H5: Valore
A6: T2_PC1 | B6: Quanto hai trovato facile ottenere informazioni sui prezzi dei biglietti e sulle biglietterie ufficiali? | F6: x | H6: =IF(C6="X",1)+IF(D6="X",2)+IF(E6="X",3)+IF(F6="X",4)+IF(G6="X",5) -> 4
B7: Self Efficacy | C7: Scarso | D7: Sufficiente | E7: Buono | F7: Molto Buono | G7: Eccellente | H7: Valore
A8: T3_SE1 | B8: Quanto sono risultate chiare, complete e leggibili le informazioni generali e le descrizioni dei luoghi proposti? | G8: x | H8: =IF(C8="X",1)+IF(D8="X",2)+IF(E8="X",3)+IF(F8="X",4)+IF(G8="X",5) -> 5
B9: Self Efficacy | C9: Scarso | D9: Sufficiente | E9: Buono | F9: Molto Buono | G9: Eccellente | H9: Valore
A10: T4_SE1 | B10: Le informazioni sull'accessibilità dei siti (es. barriere architettoniche, percorsi dedicati) ti hanno permesso di organizzare la visita in modo più consapevole e agevole? | G10: x | H10: =IF(C10="X",1)+IF(D10="X",2)+IF(E10="X",3)+IF(F10="X",4)+IF(G10="X",5) -> 5
B11: Knowledge&Skills
A12: T4_KS1 | B12: Le informazioni sull'accessibilità dei siti (es. barriere architettoniche, percorsi dedicati) sono sufficienti per chi è portatore di handicap? | G12: x | H12: =IF(C12="X",1)+IF(D12="X",2)+IF(E12="X",3)+IF(F12="X",4)+IF(G12="X",5) -> 5
B13: Personal Control
A14: T4_PC1 | B14: Le informazioni sull'accessibilità dei siti (es. barriere architettoniche, percorsi dedicati) hanno influenzato positivamente le tue decisioni sulle visite ai punti di interesse? | G14: x | H14: =IF(C14="X",1)+IF(D14="X",2)+IF(E14="X",3)+IF(F14="X",4)+IF(G14="X",5) -> 5
B15: Self Efficacy | C15: Scarso | D15: Sufficiente | E15: Buono | F15: Molto Buono | G15: Eccellente | H15: Valore
A16: T5_SE1 | B16: Quanto sono chiare e complete le informazioni tradotte nella propria lingua? | G16: x | H16: =IF(C16="X",1)+IF(D16="X",2)+IF(E16="X",3)+IF(F16="X",4)+IF(G16="X",5) -> 5
B17: Personal Control
A18: T5_PC1 | B18: Le traduzioni disponibili hanno influenzato positivamente le tue decisioni sulle visite ai punti di interesse? | G18: x | H18: =IF(C18="X",1)+IF(D18="X",2)+IF(E18="X",3)+IF(F18="X",4)+IF(G18="X",5) -> 5
B19: Motivation
A20: T5_MOT1 | B20: Conoscere le curiosità di un punto di interesse tradotto nella propria lingua ti ha motivat* a visitarlo? | G20: x | H20: =IF(C20="X",1)+IF(D20="X",2)+IF(E20="X",3)+IF(F20="X",4)+IF(G20="X",5) -> 5
B21: Personal Control | C21: Scarso | D21: Sufficiente | E21: Buono | F21: Molto Buono | G21: Eccellente | H21: Valore
A22: T6_PC1 | B22: Quanto ti è sembrato semplice e lineare il processo di creazione di un itinerario su misura per le tue esigenze? | F22: x | H22: =IF(C22="X",1)+IF(D22="X",2)+IF(E22="X",3)+IF(F22="X",4)+IF(G22="X",5) -> 4
B23: Motivation
A24: T6_MOT1 | B24: Conoscere un itinerario adatto al proprio viaggio ha influenzato positivamente la pianificazione del proprio viaggio? | G24: x | H24: =IF(C24="X",1)+IF(D24="X",2)+IF(E24="X",3)+IF(F24="X",4)+IF(G24="X",5) -> 5
B25: Motivation | C25: Scarso | D25: Sufficiente | E25: Buono | F25: Molto Buono | G25: Eccellente | H25: Valore
A26: T7_MOT1 | B26: I badge e il sistema di gamification ti ha motivat*? | E26: x | H26: =IF(C26="X",1)+IF(D26="X",2)+IF(E26="X",3)+IF(F26="X",4)+IF(G26="X",5) -> 3
B27: Personal Control | C27: Scarso | D27: Sufficiente | E27: Buono | F27: Molto Buono | G27: Eccellente | H27: Valore
A28: T8_SE1 | B28: In che misura le categorie e i filtri di ricerca proposti dal sistema rispecchiano le tue reali preferenze di viaggio e culturali? | G28: x | H28: =IF(C28="X",1)+IF(D28="X",2)+IF(E28="X",3)+IF(F28="X",4)+IF(G28="X",5) -> 5
B29: Motivation
A30: T8_MOT1 | B30: In che misura le categorie e i filtri di ricerca proposti dal sistema ti hanno motivat*? | G30: x | H30: =IF(C30="X",1)+IF(D30="X",2)+IF(E30="X",3)+IF(F30="X",4)+IF(G30="X",5) -> 5
B31: Motivation | C31: Scarso | D31: Sufficiente | E31: Buono | F31: Molto Buono | G31: Eccellente | H31: Valore
A32: T9_MOT1 | B32: Quanto ritieni che il sistema ti abbia aiutato a scoprire curiosità o approfondimenti storici/culturali sul territorio che prima non conoscevi? | G32: x | H32: =IF(C32="X",1)+IF(D32="X",2)+IF(E32="X",3)+IF(F32="X",4)+IF(G32="X",5) -> 5
B33: Knowledge&Skills | C33: Scarso | D33: Sufficiente | E33: Buono | F33: Molto Buono | G33: Eccellente | H33: Valore
A34: T10_KS1 | B34: Al termine dell'utilizzo del sistema, ti senti sufficientemente informato/a da poterti orientare nel territorio o consigliare la visita a qualcun altro? | G34: x | H34: =IF(C34="X",1)+IF(D34="X",2)+IF(E34="X",3)+IF(F34="X",4)+IF(G34="X",5) -> 5
B35: Motivation
A36: T10_MOT1 | B36: In che modo il suggerimento di un itinerario da altri utenti ha influenzato le tue visite? | F36: x | H36: =IF(C36="X",1)+IF(D36="X",2)+IF(E36="X",3)+IF(F36="X",4)+IF(G36="X",5) -> 4

Sheet Questionario #2
B1: Self Efficacy | C1: Scarso | D1: Sufficiente | E1: Buono | F1: Molto Buono | G1: Eccellente | H1: Valore
A2: T1_SE1 | B2: Quanto hai trovato chiaro e immediato reperire le informazioni pratiche di un punto di interesse (orari di apertura, prezzi o modalità di acquisto biglietti)? | G2: x | H2: =IF(C2="X",1)+IF(D2="X",2)+IF(E2="X",3)+IF(F2="X",4)+IF(G2="X",5) -> 5
B3: Personal Control
A4: T1_PC1 | B4: Quanto hai trovato facile pianificare e concordare le proprie visite consultando gli orari forniti dal sistema? | F4: x | H4: =IF(C4="X",1)+IF(D4="X",2)+IF(E4="X",3)+IF(F4="X",4)+IF(G4="X",5) -> 4
B5: Personal Control | C5: Scarso | D5: Sufficiente | E5: Buono | F5: Molto Buono | G5: Eccellente | H5: Valore
A6: T2_PC1 | B6: Quanto hai trovato facile ottenere informazioni sui prezzi dei biglietti e sulle biglietterie ufficiali? | F6: x | H6: =IF(C6="X",1)+IF(D6="X",2)+IF(E6="X",3)+IF(F6="X",4)+IF(G6="X",5) -> 4
B7: Self Efficacy | C7: Scarso | D7: Sufficiente | E7: Buono | F7: Molto Buono | G7: Eccellente | H7: Valore
A8: T3_SE1 | B8: Quanto sono risultate chiare, complete e leggibili le informazioni generali e le descrizioni dei luoghi proposti? | F8: x | H8: =IF(C8="X",1)+IF(D8="X",2)+IF(E8="X",3)+IF(F8="X",4)+IF(G8="X",5) -> 4
B9: Self Efficacy | C9: Scarso | D9: Sufficiente | E9: Buono | F9: Molto Buono | G9: Eccellente | H9: Valore
A10: T4_SE1 | B10: Le informazioni sull'accessibilità dei siti (es. barriere architettoniche, percorsi dedicati) ti hanno permesso di organizzare la visita in modo più consapevole e agevole? | F10: x | H10: =IF(C10="X",1)+IF(D10="X",2)+IF(E10="X",3)+IF(F10="X",4)+IF(G10="X",5) -> 4
B11: Knowledge&Skills
A12: T4_KS1 | B12: Le informazioni sull'accessibilità dei siti (es. barriere architettoniche, percorsi dedicati) sono sufficienti per chi è portatore di handicap? | F12: x | H12: =IF(C12="X",1)+IF(D12="X",2)+IF(E12="X",3)+IF(F12="X",4)+IF(G12="X",5) -> 4
B13: Personal Control
A14: T4_PC1 | B14: Le informazioni sull'accessibilità dei siti (es. barriere architettoniche, percorsi dedicati) hanno influenzato positivamente le tue decisioni sulle visite ai punti di interesse? | G14: x | H14: =IF(C14="X",1)+IF(D14="X",2)+IF(E14="X",3)+IF(F14="X",4)+IF(G14="X",5) -> 5
B15: Self Efficacy | C15: Scarso | D15: Sufficiente | E15: Buono | F15: Molto Buono | G15: Eccellente | H15: Valore
A16: T5_SE1 | B16: Quanto sono chiare e complete le informazioni tradotte nella propria lingua? | D16: x | H16: =IF(C16="X",1)+IF(D16="X",2)+IF(E16="X",3)+IF(F16="X",4)+IF(G16="X",5) -> 2
B17: Personal Control
A18: T5_PC1 | B18: Le traduzioni disponibili hanno influenzato positivamente le tue decisioni sulle visite ai punti di interesse? | G18: x | H18: =IF(C18="X",1)+IF(D18="X",2)+IF(E18="X",3)+IF(F18="X",4)+IF(G18="X",5) -> 5
B19: Motivation
A20: T5_MOT1 | B20: Conoscere le curiosità di un punto di interesse tradotto nella propria lingua ti ha motivat* a visitarlo? | F20: x | H20: =IF(C20="X",1)+IF(D20="X",2)+IF(E20="X",3)+IF(F20="X",4)+IF(G20="X",5) -> 4
B21: Personal Control | C21: Scarso | D21: Sufficiente | E21: Buono | F21: Molto Buono | G21: Eccellente | H21: Valore
A22: T6_PC1 | B22: Quanto ti è sembrato semplice e lineare il processo di creazione di un itinerario su misura per le tue esigenze? | F22: x | H22: =IF(C22="X",1)+IF(D22="X",2)+IF(E22="X",3)+IF(F22="X",4)+IF(G22="X",5) -> 4
B23: Motivation
A24: T6_MOT1 | B24: Conoscere un itinerario adatto al proprio viaggio ha influenzato positivamente la pianificazione del proprio viaggio? | G24: x | H24: =IF(C24="X",1)+IF(D24="X",2)+IF(E24="X",3)+IF(F24="X",4)+IF(G24="X",5) -> 5
B25: Motivation | C25: Scarso | D25: Sufficiente | E25: Buono | F25: Molto Buono | G25: Eccellente | H25: Valore
A26: T7_MOT1 | B26: I badge e il sistema di gamification ti ha motivat*? | G26: x | H26: =IF(C26="X",1)+IF(D26="X",2)+IF(E26="X",3)+IF(F26="X",4)+IF(G26="X",5) -> 5
B27: Personal Control | C27: Scarso | D27: Sufficiente | E27: Buono | F27: Molto Buono | G27: Eccellente | H27: Valore
A28: T8_SE1 | B28: In che misura le categorie e i filtri di ricerca proposti dal sistema rispecchiano le tue reali preferenze di viaggio e culturali? | E28: x | H28: =IF(C28="X",1)+IF(D28="X",2)+IF(E28="X",3)+IF(F28="X",4)+IF(G28="X",5) -> 3
B29: Motivation
A30: T8_MOT1 | B30: In che misura le categorie e i filtri di ricerca proposti dal sistema ti hanno motivat*? | F30: x | H30: =IF(C30="X",1)+IF(D30="X",2)+IF(E30="X",3)+IF(F30="X",4)+IF(G30="X",5) -> 4
B31: Motivation | C31: Scarso | D31: Sufficiente | E31: Buono | F31: Molto Buono | G31: Eccellente | H31: Valore
A32: T9_MOT1 | B32: Quanto ritieni che il sistema ti abbia aiutato a scoprire curiosità o approfondimenti storici/culturali sul territorio che prima non conoscevi? | G32: x | H32: =IF(C32="X",1)+IF(D32="X",2)+IF(E32="X",3)+IF(F32="X",4)+IF(G32="X",5) -> 5
B33: Knowledge&Skills | C33: Scarso | D33: Sufficiente | E33: Buono | F33: Molto Buono | G33: Eccellente | H33: Valore
A34: T10_KS1 | B34: Al termine dell'utilizzo del sistema, ti senti sufficientemente informato/a da poterti orientare nel territorio o consigliare la visita a qualcun altro? | G34: x | H34: =IF(C34="X",1)+IF(D34="X",2)+IF(E34="X",3)+IF(F34="X",4)+IF(G34="X",5) -> 5
B35: Motivation
A36: T10_MOT1 | B36: In che modo il suggerimento di un itinerario da altri utenti ha influenzato le tue visite? | F36: x | H36: =IF(C36="X",1)+IF(D36="X",2)+IF(E36="X",3)+IF(F36="X",4)+IF(G36="X",5) -> 4

Sheet Questionario #3
A1: Questionario # | B1: Self Efficacy | C1: Scarso | D1: Sufficiente | E1: Buono | F1: Molto Buono | G1: Eccellente | H1: Valore
A2: T1_SE1 | B2: Quanto hai trovato chiaro e immediato reperire le informazioni pratiche di un punto di interesse (orari di apertura, prezzi o modalità di acquisto biglietti)? | F2: x | H2: =IF(C2="X",1)+IF(D2="X",2)+IF(E2="X",3)+IF(F2="X",4)+IF(G2="X",5) -> 4
B3: Personal Control
A4: T1_PC1 | B4: Quanto hai trovato facile pianificare e concordare le proprie visite consultando gli orari forniti dal sistema? | F4: x | H4: =IF(C4="X",1)+IF(D4="X",2)+IF(E4="X",3)+IF(F4="X",4)+IF(G4="X",5) -> 4
B5: Personal Control | C5: Scarso | D5: Sufficiente | E5: Buono | F5: Molto Buono | G5: Eccellente | H5: Valore
A6: T2_PC1 | B6: Quanto hai trovato facile ottenere informazioni sui prezzi dei biglietti e sulle biglietterie ufficiali? | F6: x | H6: =IF(C6="X",1)+IF(D6="X",2)+IF(E6="X",3)+IF(F6="X",4)+IF(G6="X",5) -> 4
B7: Self Efficacy | C7: Scarso | D7: Sufficiente | E7: Buono | F7: Molto Buono | G7: Eccellente | H7: Valore
A8: T3_SE1 | B8: Quanto sono risultate chiare, complete e leggibili le informazioni generali e le descrizioni dei luoghi proposti? | F8: x | H8: =IF(C8="X",1)+IF(D8="X",2)+IF(E8="X",3)+IF(F8="X",4)+IF(G8="X",5) -> 4
B9: Self Efficacy | C9: Scarso | D9: Sufficiente | E9: Buono | F9: Molto Buono | G9: Eccellente | H9: Valore
A10: T4_SE1 | B10: Le informazioni sull'accessibilità dei siti (es. barriere architettoniche, percorsi dedicati) ti hanno permesso di organizzare la visita in modo più consapevole e agevole? | G10: x | H10: =IF(C10="X",1)+IF(D10="X",2)+IF(E10="X",3)+IF(F10="X",4)+IF(G10="X",5) -> 5
B11: Knowledge&Skills
A12: T4_KS1 | B12: Le informazioni sull'accessibilità dei siti (es. barriere architettoniche, percorsi dedicati) sono sufficienti per chi è portatore di handicap? | F12: x | H12: =IF(C12="X",1)+IF(D12="X",2)+IF(E12="X",3)+IF(F12="X",4)+IF(G12="X",5) -> 4
B13: Personal Control
A14: T4_PC1 | B14: Le informazioni sull'accessibilità dei siti (es. barriere architettoniche, percorsi dedicati) hanno influenzato positivamente le tue decisioni sulle visite ai punti di interesse? | G14: x | H14: =IF(C14="X",1)+IF(D14="X",2)+IF(E14="X",3)+IF(F14="X",4)+IF(G14="X",5) -> 5
B15: Self Efficacy | C15: Scarso | D15: Sufficiente | E15: Buono | F15: Molto Buono | G15: Eccellente | H15: Valore
A16: T5_SE1 | B16: Quanto sono chiare e complete le informazioni tradotte nella propria lingua? | F16: x | H16: =IF(C16="X",1)+IF(D16="X",2)+IF(E16="X",3)+IF(F16="X",4)+IF(G16="X",5) -> 4
B17: Personal Control
A18: T5_PC1 | B18: Le traduzioni disponibili hanno influenzato positivamente le tue decisioni sulle visite ai punti di interesse? | E18: x | H18: =IF(C18="X",1)+IF(D18="X",2)+IF(E18="X",3)+IF(F18="X",4)+IF(G18="X",5) -> 3
B19: Motivation
A20: T5_MOT1 | B20: Conoscere le curiosità di un punto di interesse tradotto nella propria lingua ti ha motivat* a visitarlo? | F20: x | H20: =IF(C20="X",1)+IF(D20="X",2)+IF(E20="X",3)+IF(F20="X",4)+IF(G20="X",5) -> 4
B21: Personal Control | C21: Scarso | D21: Sufficiente | E21: Buono | F21: Molto Buono | G21: Eccellente | H21: Valore
A22: T6_PC1 | B22: Quanto ti è sembrato semplice e lineare il processo di creazione di un itinerario su misura per le tue esigenze? | F22: x | H22: =IF(C22="X",1)+IF(D22="X",2)+IF(E22="X",3)+IF(F22="X",4)+IF(G22="X",5) -> 4
B23: Motivation
A24: T6_MOT1 | B24: Conoscere un itinerario adatto al proprio viaggio ha influenzato positivamente la pianificazione del proprio viaggio? | F24: x | H24: =IF(C24="X",1)+IF(D24="X",2)+IF(E24="X",3)+IF(F24="X",4)+IF(G24="X",5) -> 4
B25: Motivation | C25: Scarso | D25: Sufficiente | E25: Buono | F25: Molto Buono | G25: Eccellente | H25: Valore
A26: T7_MOT1 | B26: I badge e il sistema di gamification ti ha motivat*? | E26: x | H26: =IF(C26="X",1)+IF(D26="X",2)+IF(E26="X",3)+IF(F26="X",4)+IF(G26="X",5) -> 3
B27: Personal Control | C27: Scarso | D27: Sufficiente | E27: Buono | F27: Molto Buono | G27: Eccellente | H27: Valore
A28: T8_SE1 | B28: In che misura le categorie e i filtri di ricerca proposti dal sistema rispecchiano le tue reali preferenze di viaggio e culturali? | E28: x | H28: =IF(C28="X",1)+IF(D28="X",2)+IF(E28="X",3)+IF(F28="X",4)+IF(G28="X",5) -> 3
B29: Motivation
A30: T8_MOT1 | B30: In che misura le categorie e i filtri di ricerca proposti dal sistema ti hanno motivat*? | F30: x | H30: =IF(C30="X",1)+IF(D30="X",2)+IF(E30="X",3)+IF(F30="X",4)+IF(G30="X",5) -> 4
B31: Motivation | C31: Scarso | D31: Sufficiente | E31: Buono | F31: Molto Buono | G31: Eccellente | H31: Valore
A32: T9_MOT1 | B32: Quanto ritieni che il sistema ti abbia aiutato a scoprire curiosità o approfondimenti storici/culturali sul territorio che prima non conoscevi? | F32: x | H32: =IF(C32="X",1)+IF(D32="X",2)+IF(E32="X",3)+IF(F32="X",4)+IF(G32="X",5) -> 4
B33: Knowledge&Skills | C33: Scarso | D33: Sufficiente | E33: Buono | F33: Molto Buono | G33: Eccellente | H33: Valore
A34: T10_KS1 | B34: Al termine dell'utilizzo del sistema, ti senti sufficientemente informato/a da poterti orientare nel territorio o consigliare la visita a qualcun altro? | E34: x | H34: =IF(C34="X",1)+IF(D34="X",2)+IF(E34="X",3)+IF(F34="X",4)+IF(G34="X",5) -> 3
B35: Motivation
A36: T10_MOT1 | B36: In che modo il suggerimento di un itinerario da altri utenti ha influenzato le tue visite? | F36: x | H36: =IF(C36="X",1)+IF(D36="X",2)+IF(E36="X",3)+IF(F36="X",4)+IF(G36="X",5) -> 4

Sheet Questionario #4
B1: Self Efficacy | C1: Scarso | D1: Sufficiente | E1: Buono | F1: Molto Buono | G1: Eccellente | H1: Valore
A2: T1_SE1 | B2: Quanto hai trovato chiaro e immediato reperire le informazioni pratiche di un punto di interesse (orari di apertura, prezzi o modalità di acquisto biglietti)? | G2: x | H2: =IF(C2="X",1)+IF(D2="X",2)+IF(E2="X",3)+IF(F2="X",4)+IF(G2="X",5) -> 5
B3: Personal Control
A4: T1_PC1 | B4: Quanto hai trovato facile pianificare e concordare le proprie visite consultando gli orari forniti dal sistema? | G4: x | H4: =IF(C4="X",1)+IF(D4="X",2)+IF(E4="X",3)+IF(F4="X",4)+IF(G4="X",5) -> 5
B5: Personal Control | C5: Scarso | D5: Sufficiente | E5: Buono | F5: Molto Buono | G5: Eccellente | H5: Valore
A6: T2_PC1 | B6: Quanto hai trovato facile ottenere informazioni sui prezzi dei biglietti e sulle biglietterie ufficiali? | G6: x | H6: =IF(C6="X",1)+IF(D6="X",2)+IF(E6="X",3)+IF(F6="X",4)+IF(G6="X",5) -> 5
B7: Self Efficacy | C7: Scarso | D7: Sufficiente | E7: Buono | F7: Molto Buono | G7: Eccellente | H7: Valore
A8: T3_SE1 | B8: Quanto sono risultate chiare, complete e leggibili le informazioni generali e le descrizioni dei luoghi proposti? | F8: x | H8: =IF(C8="X",1)+IF(D8="X",2)+IF(E8="X",3)+IF(F8="X",4)+IF(G8="X",5) -> 4
B9: Self Efficacy | C9: Scarso | D9: Sufficiente | E9: Buono | F9: Molto Buono | G9: Eccellente | H9: Valore
A10: T4_SE1 | B10: Le informazioni sull'accessibilità dei siti (es. barriere architettoniche, percorsi dedicati) ti hanno permesso di organizzare la visita in modo più consapevole e agevole? | F10: x | H10: =IF(C10="X",1)+IF(D10="X",2)+IF(E10="X",3)+IF(F10="X",4)+IF(G10="X",5) -> 4
B11: Knowledge&Skills
A12: T4_KS1 | B12: Le informazioni sull'accessibilità dei siti (es. barriere architettoniche, percorsi dedicati) sono sufficienti per chi è portatore di handicap? | F12: x | H12: =IF(C12="X",1)+IF(D12="X",2)+IF(E12="X",3)+IF(F12="X",4)+IF(G12="X",5) -> 4
B13: Personal Control
A14: T4_PC1 | B14: Le informazioni sull'accessibilità dei siti (es. barriere architettoniche, percorsi dedicati) hanno influenzato positivamente le tue decisioni sulle visite ai punti di interesse? | G14: x | H14: =IF(C14="X",1)+IF(D14="X",2)+IF(E14="X",3)+IF(F14="X",4)+IF(G14="X",5) -> 5
B15: Self Efficacy | C15: Scarso | D15: Sufficiente | E15: Buono | F15: Molto Buono | G15: Eccellente | H15: Valore
A16: T5_SE1 | B16: Quanto sono chiare e complete le informazioni tradotte nella propria lingua? | F16: x | H16: =IF(C16="X",1)+IF(D16="X",2)+IF(E16="X",3)+IF(F16="X",4)+IF(G16="X",5) -> 4
B17: Personal Control
A18: T5_PC1 | B18: Le traduzioni disponibili hanno influenzato positivamente le tue decisioni sulle visite ai punti di interesse? | F18: x | H18: =IF(C18="X",1)+IF(D18="X",2)+IF(E18="X",3)+IF(F18="X",4)+IF(G18="X",5) -> 4
B19: Motivation
A20: T5_MOT1 | B20: Conoscere le curiosità di un punto di interesse tradotto nella propria lingua ti ha motivat* a visitarlo? | E20: x | H20: =IF(C20="X",1)+IF(D20="X",2)+IF(E20="X",3)+IF(F20="X",4)+IF(G20="X",5) -> 3
B21: Personal Control | C21: Scarso | D21: Sufficiente | E21: Buono | F21: Molto Buono | G21: Eccellente | H21: Valore
A22: T6_PC1 | B22: Quanto ti è sembrato semplice e lineare il processo di creazione di un itinerario su misura per le tue esigenze? | G22: x | H22: =IF(C22="X",1)+IF(D22="X",2)+IF(E22="X",3)+IF(F22="X",4)+IF(G22="X",5) -> 5
B23: Motivation
A24: T6_MOT1 | B24: Conoscere un itinerario adatto al proprio viaggio ha influenzato positivamente la pianificazione del proprio viaggio? | E24: x | H24: =IF(C24="X",1)+IF(D24="X",2)+IF(E24="X",3)+IF(F24="X",4)+IF(G24="X",5) -> 3
B25: Motivation | C25: Scarso | D25: Sufficiente | E25: Buono | F25: Molto Buono | G25: Eccellente | H25: Valore
A26: T7_MOT1 | B26: I badge e il sistema di gamification ti ha motivat*? | G26: x | H26: =IF(C26="X",1)+IF(D26="X",2)+IF(E26="X",3)+IF(F26="X",4)+IF(G26="X",5) -> 5
B27: Personal Control | C27: Scarso | D27: Sufficiente | E27: Buono | F27: Molto Buono | G27: Eccellente | H27: Valore
A28: T8_SE1 | B28: In che misura le categorie e i filtri di ricerca proposti dal sistema rispecchiano le tue reali preferenze di viaggio e culturali? | F28: x | H28: =IF(C28="X",1)+IF(D28="X",2)+IF(E28="X",3)+IF(F28="X",4)+IF(G28="X",5) -> 4
B29: Motivation
A30: T8_MOT1 | B30: In che misura le categorie e i filtri di ricerca proposti dal sistema ti hanno motivat*? | F30: x | H30: =IF(C30="X",1)+IF(D30="X",2)+IF(E30="X",3)+IF(F30="X",4)+IF(G30="X",5) -> 4
B31: Motivation | C31: Scarso | D31: Sufficiente | E31: Buono | F31: Molto Buono | G31: Eccellente | H31: Valore
A32: T9_MOT1 | B32: Quanto ritieni che il sistema ti abbia aiutato a scoprire curiosità o approfondimenti storici/culturali sul territorio che prima non conoscevi? | F32: x | H32: =IF(C32="X",1)+IF(D32="X",2)+IF(E32="X",3)+IF(F32="X",4)+IF(G32="X",5) -> 4
B33: Knowledge&Skills | C33: Scarso | D33: Sufficiente | E33: Buono | F33: Molto Buono | G33: Eccellente | H33: Valore
A34: T10_KS1 | B34: Al termine dell'utilizzo del sistema, ti senti sufficientemente informato/a da poterti orientare nel territorio o consigliare la visita a qualcun altro? | E34: x | H34: =IF(C34="X",1)+IF(D34="X",2)+IF(E34="X",3)+IF(F34="X",4)+IF(G34="X",5) -> 3
B35: Motivation
A36: T10_MOT1 | B36: In che modo il suggerimento di un itinerario da altri utenti ha influenzato le tue visite? | G36: x | H36: =IF(C36="X",1)+IF(D36="X",2)+IF(E36="X",3)+IF(F36="X",4)+IF(G36="X",5) -> 5

Sheet Questionario #5
B1: Self Efficacy | C1: Scarso | D1: Sufficiente | E1: Buono | F1: Molto Buono | G1: Eccellente | H1: Valore
A2: T1_SE1 | B2: Quanto hai trovato chiaro e immediato reperire le informazioni pratiche di un punto di interesse (orari di apertura, prezzi o modalità di acquisto biglietti)? | F2: x | H2: =IF(C2="X",1)+IF(D2="X",2)+IF(E2="X",3)+IF(F2="X",4)+IF(G2="X",5) -> 4
B3: Personal Control
A4: T1_PC1 | B4: Quanto hai trovato facile pianificare e concordare le proprie visite consultando gli orari forniti dal sistema? | E4: x | H4: =IF(C4="X",1)+IF(D4="X",2)+IF(E4="X",3)+IF(F4="X",4)+IF(G4="X",5) -> 3
B5: Personal Control | C5: Scarso | D5: Sufficiente | E5: Buono | F5: Molto Buono | G5: Eccellente | H5: Valore
A6: T2_PC1 | B6: Quanto hai trovato facile ottenere informazioni sui prezzi dei biglietti e sulle biglietterie ufficiali? | G6: x | H6: =IF(C6="X",1)+IF(D6="X",2)+IF(E6="X",3)+IF(F6="X",4)+IF(G6="X",5) -> 5
B7: Self Efficacy | C7: Scarso | D7: Sufficiente | E7: Buono | F7: Molto Buono | G7: Eccellente | H7: Valore
A8: T3_SE1 | B8: Quanto sono risultate chiare, complete e leggibili le informazioni generali e le descrizioni dei luoghi proposti? | G8: x | H8: =IF(C8="X",1)+IF(D8="X",2)+IF(E8="X",3)+IF(F8="X",4)+IF(G8="X",5) -> 5
B9: Self Efficacy | C9: Scarso | D9: Sufficiente | E9: Buono | F9: Molto Buono | G9: Eccellente | H9: Valore
A10: T4_SE1 | B10: Le informazioni sull'accessibilità dei siti (es. barriere architettoniche, percorsi dedicati) ti hanno permesso di organizzare la visita in modo più consapevole e agevole? | F10: x | H10: =IF(C10="X",1)+IF(D10="X",2)+IF(E10="X",3)+IF(F10="X",4)+IF(G10="X",5) -> 4
B11: Knowledge&Skills
A12: T4_KS1 | B12: Le informazioni sull'accessibilità dei siti (es. barriere architettoniche, percorsi dedicati) sono sufficienti per chi è portatore di handicap? | E12: x | H12: =IF(C12="X",1)+IF(D12="X",2)+IF(E12="X",3)+IF(F12="X",4)+IF(G12="X",5) -> 3
B13: Personal Control
A14: T4_PC1 | B14: Le informazioni sull'accessibilità dei siti (es. barriere architettoniche, percorsi dedicati) hanno influenzato positivamente le tue decisioni sulle visite ai punti di interesse? | G14: x | H14: =IF(C14="X",1)+IF(D14="X",2)+IF(E14="X",3)+IF(F14="X",4)+IF(G14="X",5) -> 5
B15: Self Efficacy | C15: Scarso | D15: Sufficiente | E15: Buono | F15: Molto Buono | G15: Eccellente | H15: Valore
A16: T5_SE1 | B16: Quanto sono chiare e complete le informazioni tradotte nella propria lingua? | E16: x | H16: =IF(C16="X",1)+IF(D16="X",2)+IF(E16="X",3)+IF(F16="X",4)+IF(G16="X",5) -> 3
B17: Personal Control
A18: T5_PC1 | B18: Le traduzioni disponibili hanno influenzato positivamente le tue decisioni sulle visite ai punti di interesse? | F18: x | H18: =IF(C18="X",1)+IF(D18="X",2)+IF(E18="X",3)+IF(F18="X",4)+IF(G18="X",5) -> 4
B19: Motivation
A20: T5_MOT1 | B20: Conoscere le curiosità di un punto di interesse tradotto nella propria lingua ti ha motivat* a visitarlo? | F20: x | H20: =IF(C20="X",1)+IF(D20="X",2)+IF(E20="X",3)+IF(F20="X",4)+IF(G20="X",5) -> 4
B21: Personal Control | C21: Scarso | D21: Sufficiente | E21: Buono | F21: Molto Buono | G21: Eccellente | H21: Valore
A22: T6_PC1 | B22: Quanto ti è sembrato semplice e lineare il processo di creazione di un itinerario su misura per le tue esigenze? | G22: x | H22: =IF(C22="X",1)+IF(D22="X",2)+IF(E22="X",3)+IF(F22="X",4)+IF(G22="X",5) -> 5
B23: Motivation
A24: T6_MOT1 | B24: Conoscere un itinerario adatto al proprio viaggio ha influenzato positivamente la pianificazione del proprio viaggio? | G24: x | H24: =IF(C24="X",1)+IF(D24="X",2)+IF(E24="X",3)+IF(F24="X",4)+IF(G24="X",5) -> 5
B25: Motivation | C25: Scarso | D25: Sufficiente | E25: Buono | F25: Molto Buono | G25: Eccellente | H25: Valore
A26: T7_MOT1 | B26: I badge e il sistema di gamification ti ha motivat*? | F26: x | H26: =IF(C26="X",1)+IF(D26="X",2)+IF(E26="X",3)+IF(F26="X",4)+IF(G26="X",5) -> 4
B27: Personal Control | C27: Scarso | D27: Sufficiente | E27: Buono | F27: Molto Buono | G27: Eccellente | H27: Valore
A28: T8_SE1 | B28: In che misura le categorie e i filtri di ricerca proposti dal sistema rispecchiano le tue reali preferenze di viaggio e culturali? | F28: x | H28: =IF(C28="X",1)+IF(D28="X",2)+IF(E28="X",3)+IF(F28="X",4)+IF(G28="X",5) -> 4
B29: Motivation
A30: T8_MOT1 | B30: In che misura le categorie e i filtri di ricerca proposti dal sistema ti hanno motivat*? | E30: x | H30: =IF(C30="X",1)+IF(D30="X",2)+IF(E30="X",3)+IF(F30="X",4)+IF(G30="X",5) -> 3
B31: Motivation | C31: Scarso | D31: Sufficiente | E31: Buono | F31: Molto Buono | G31: Eccellente | H31: Valore
A32: T9_MOT1 | B32: Quanto ritieni che il sistema ti abbia aiutato a scoprire curiosità o approfondimenti storici/culturali sul territorio che prima non conoscevi? | G32: x | H32: =IF(C32="X",1)+IF(D32="X",2)+IF(E32="X",3)+IF(F32="X",4)+IF(G32="X",5) -> 5
B33: Knowledge&Skills | C33: Scarso | D33: Sufficiente | E33: Buono | F33: Molto Buono | G33: Eccellente | H33: Valore
A34: T10_KS1 | B34: Al termine dell'utilizzo del sistema, ti senti sufficientemente informato/a da poterti orientare nel territorio o consigliare la visita a qualcun altro? | F34: x | H34: =IF(C34="X",1)+IF(D34="X",2)+IF(E34="X",3)+IF(F34="X",4)+IF(G34="X",5) -> 4
B35: Motivation
A36: T10_MOT1 | B36: In che modo il suggerimento di un itinerario da altri utenti ha influenzato le tue visite? | E36: x | H36: =IF(C36="X",1)+IF(D36="X",2)+IF(E36="X",3)+IF(F36="X",4)+IF(G36="X",5) -> 3

Sheet Questionario #6
B1: Self Efficacy | C1: Scarso | D1: Sufficiente | E1: Buono | F1: Molto Buono | G1: Eccellente | H1: Valore
A2: T1_SE1 | B2: Quanto hai trovato chiaro e immediato reperire le informazioni pratiche di un punto di interesse (orari di apertura, prezzi o modalità di acquisto biglietti)? | G2: x | H2: =IF(C2="X",1)+IF(D2="X",2)+IF(E2="X",3)+IF(F2="X",4)+IF(G2="X",5) -> 5
B3: Personal Control
A4: T1_PC1 | B4: Quanto hai trovato facile pianificare e concordare le proprie visite consultando gli orari forniti dal sistema? | G4: x | H4: =IF(C4="X",1)+IF(D4="X",2)+IF(E4="X",3)+IF(F4="X",4)+IF(G4="X",5) -> 5
B5: Personal Control | C5: Scarso | D5: Sufficiente | E5: Buono | F5: Molto Buono | G5: Eccellente | H5: Valore
A6: T2_PC1 | B6: Quanto hai trovato facile ottenere informazioni sui prezzi dei biglietti e sulle biglietterie ufficiali? | F6: x | H6: =IF(C6="X",1)+IF(D6="X",2)+IF(E6="X",3)+IF(F6="X",4)+IF(G6="X",5) -> 4
B7: Self Efficacy | C7: Scarso | D7: Sufficiente | E7: Buono | F7: Molto Buono | G7: Eccellente | H7: Valore
A8: T3_SE1 | B8: Quanto sono risultate chiare, complete e leggibili le informazioni generali e le descrizioni dei luoghi proposti? | G8: x | H8: =IF(C8="X",1)+IF(D8="X",2)+IF(E8="X",3)+IF(F8="X",4)+IF(G8="X",5) -> 5
B9: Self Efficacy | C9: Scarso | D9: Sufficiente | E9: Buono | F9: Molto Buono | G9: Eccellente | H9: Valore
A10: T4_SE1 | B10: Le informazioni sull'accessibilità dei siti (es. barriere architettoniche, percorsi dedicati) ti hanno permesso di organizzare la visita in modo più consapevole e agevole? | G10: x | H10: =IF(C10="X",1)+IF(D10="X",2)+IF(E10="X",3)+IF(F10="X",4)+IF(G10="X",5) -> 5
B11: Knowledge&Skills
A12: T4_KS1 | B12: Le informazioni sull'accessibilità dei siti (es. barriere architettoniche, percorsi dedicati) sono sufficienti per chi è portatore di handicap? | F12: x | H12: =IF(C12="X",1)+IF(D12="X",2)+IF(E12="X",3)+IF(F12="X",4)+IF(G12="X",5) -> 4
B13: Personal Control
A14: T4_PC1 | B14: Le informazioni sull'accessibilità dei siti (es. barriere architettoniche, percorsi dedicati) hanno influenzato positivamente le tue decisioni sulle visite ai punti di interesse? | G14: x | H14: =IF(C14="X",1)+IF(D14="X",2)+IF(E14="X",3)+IF(F14="X",4)+IF(G14="X",5) -> 5
B15: Self Efficacy | C15: Scarso | D15: Sufficiente | E15: Buono | F15: Molto Buono | G15: Eccellente | H15: Valore
A16: T5_SE1 | B16: Quanto sono chiare e complete le informazioni tradotte nella propria lingua? | G16: x | H16: =IF(C16="X",1)+IF(D16="X",2)+IF(E16="X",3)+IF(F16="X",4)+IF(G16="X",5) -> 5
B17: Personal Control
A18: T5_PC1 | B18: Le traduzioni disponibili hanno influenzato positivamente le tue decisioni sulle visite ai punti di interesse? | F18: x | H18: =IF(C18="X",1)+IF(D18="X",2)+IF(E18="X",3)+IF(F18="X",4)+IF(G18="X",5) -> 4
B19: Motivation
A20: T5_MOT1 | B20: Conoscere le curiosità di un punto di interesse tradotto nella propria lingua ti ha motivat* a visitarlo? | F20: x | H20: =IF(C20="X",1)+IF(D20="X",2)+IF(E20="X",3)+IF(F20="X",4)+IF(G20="X",5) -> 4
B21: Personal Control | C21: Scarso | D21: Sufficiente | E21: Buono | F21: Molto Buono | G21: Eccellente | H21: Valore
A22: T6_PC1 | B22: Quanto ti è sembrato semplice e lineare il processo di creazione di un itinerario su misura per le tue esigenze? | G22: x | H22: =IF(C22="X",1)+IF(D22="X",2)+IF(E22="X",3)+IF(F22="X",4)+IF(G22="X",5) -> 5
B23: Motivation
A24: T6_MOT1 | B24: Conoscere un itinerario adatto al proprio viaggio ha influenzato positivamente la pianificazione del proprio viaggio? | G24: x | H24: =IF(C24="X",1)+IF(D24="X",2)+IF(E24="X",3)+IF(F24="X",4)+IF(G24="X",5) -> 5
B25: Motivation | C25: Scarso | D25: Sufficiente | E25: Buono | F25: Molto Buono | G25: Eccellente | H25: Valore
A26: T7_MOT1 | B26: I badge e il sistema di gamification ti ha motivat*? | E26: x | H26: =IF(C26="X",1)+IF(D26="X",2)+IF(E26="X",3)+IF(F26="X",4)+IF(G26="X",5) -> 3
B27: Personal Control | C27: Scarso | D27: Sufficiente | E27: Buono | F27: Molto Buono | G27: Eccellente | H27: Valore
A28: T8_SE1 | B28: In che misura le categorie e i filtri di ricerca proposti dal sistema rispecchiano le tue reali preferenze di viaggio e culturali? | F28: x | H28: =IF(C28="X",1)+IF(D28="X",2)+IF(E28="X",3)+IF(F28="X",4)+IF(G28="X",5) -> 4
B29: Motivation
A30: T8_MOT1 | B30: In che misura le categorie e i filtri di ricerca proposti dal sistema ti hanno motivat*? | G30: x | H30: =IF(C30="X",1)+IF(D30="X",2)+IF(E30="X",3)+IF(F30="X",4)+IF(G30="X",5) -> 5
B31: Motivation | C31: Scarso | D31: Sufficiente | E31: Buono | F31: Molto Buono | G31: Eccellente | H31: Valore
A32: T9_MOT1 | B32: Quanto ritieni che il sistema ti abbia aiutato a scoprire curiosità o approfondimenti storici/culturali sul territorio che prima non conoscevi? | G32: x | H32: =IF(C32="X",1)+IF(D32="X",2)+IF(E32="X",3)+IF(F32="X",4)+IF(G32="X",5) -> 5
B33: Knowledge&Skills | C33: Scarso | D33: Sufficiente | E33: Buono | F33: Molto Buono | G33: Eccellente | H33: Valore
A34: T10_KS1 | B34: Al termine dell'utilizzo del sistema, ti senti sufficientemente informato/a da poterti orientare nel territorio o consigliare la visita a qualcun altro? | G34: x | H34: =IF(C34="X",1)+IF(D34="X",2)+IF(E34="X",3)+IF(F34="X",4)+IF(G34="X",5) -> 5
B35: Motivation
A36: T10_MOT1 | B36: In che modo il suggerimento di un itinerario da altri utenti ha influenzato le tue visite? | F36: x | H36: =IF(C36="X",1)+IF(D36="X",2)+IF(E36="X",3)+IF(F36="X",4)+IF(G36="X",5) -> 4

Sheet Questionario #7
B1: Self Efficacy | C1: Scarso | D1: Sufficiente | E1: Buono | F1: Molto Buono | G1: Eccellente | H1: Valore
A2: T1_SE1 | B2: Quanto hai trovato chiaro e immediato reperire le informazioni pratiche di un punto di interesse (orari di apertura, prezzi o modalità di acquisto biglietti)? | G2: x | H2: =IF(C2="X",1)+IF(D2="X",2)+IF(E2="X",3)+IF(F2="X",4)+IF(G2="X",5) -> 5
B3: Personal Control
A4: T1_PC1 | B4: Quanto hai trovato facile pianificare e concordare le proprie visite consultando gli orari forniti dal sistema? | F4: x | H4: =IF(C4="X",1)+IF(D4="X",2)+IF(E4="X",3)+IF(F4="X",4)+IF(G4="X",5) -> 4
B5: Personal Control | C5: Scarso | D5: Sufficiente | E5: Buono | F5: Molto Buono | G5: Eccellente | H5: Valore
A6: T2_PC1 | B6: Quanto hai trovato facile ottenere informazioni sui prezzi dei biglietti e sulle biglietterie ufficiali? | F6: x | H6: =IF(C6="X",1)+IF(D6="X",2)+IF(E6="X",3)+IF(F6="X",4)+IF(G6="X",5) -> 4
B7: Self Efficacy | C7: Scarso | D7: Sufficiente | E7: Buono | F7: Molto Buono | G7: Eccellente | H7: Valore
A8: T3_SE1 | B8: Quanto sono risultate chiare, complete e leggibili le informazioni generali e le descrizioni dei luoghi proposti? | E8: x | H8: =IF(C8="X",1)+IF(D8="X",2)+IF(E8="X",3)+IF(F8="X",4)+IF(G8="X",5) -> 3
B9: Self Efficacy | C9: Scarso | D9: Sufficiente | E9: Buono | F9: Molto Buono | G9: Eccellente | H9: Valore
A10: T4_SE1 | B10: Le informazioni sull'accessibilità dei siti (es. barriere architettoniche, percorsi dedicati) ti hanno permesso di organizzare la visita in modo più consapevole e agevole? | F10: x | H10: =IF(C10="X",1)+IF(D10="X",2)+IF(E10="X",3)+IF(F10="X",4)+IF(G10="X",5) -> 4
B11: Knowledge&Skills
A12: T4_KS1 | B12: Le informazioni sull'accessibilità dei siti (es. barriere architettoniche, percorsi dedicati) sono sufficienti per chi è portatore di handicap? | E12: x | H12: =IF(C12="X",1)+IF(D12="X",2)+IF(E12="X",3)+IF(F12="X",4)+IF(G12="X",5) -> 3
B13: Personal Control
A14: T4_PC1 | B14: Le informazioni sull'accessibilità dei siti (es. barriere architettoniche, percorsi dedicati) hanno influenzato positivamente le tue decisioni sulle visite ai punti di interesse? | G14: x | H14: =IF(C14="X",1)+IF(D14="X",2)+IF(E14="X",3)+IF(F14="X",4)+IF(G14="X",5) -> 5
B15: Self Efficacy | C15: Scarso | D15: Sufficiente | E15: Buono | F15: Molto Buono | G15: Eccellente | H15: Valore
A16: T5_SE1 | B16: Quanto sono chiare e complete le informazioni tradotte nella propria lingua? | D16: x | H16: =IF(C16="X",1)+IF(D16="X",2)+IF(E16="X",3)+IF(F16="X",4)+IF(G16="X",5) -> 2
B17: Personal Control
A18: T5_PC1 | B18: Le traduzioni disponibili hanno influenzato positivamente le tue decisioni sulle visite ai punti di interesse? | E18: x | H18: =IF(C18="X",1)+IF(D18="X",2)+IF(E18="X",3)+IF(F18="X",4)+IF(G18="X",5) -> 3
B19: Motivation
A20: T5_MOT1 | B20: Conoscere le curiosità di un punto di interesse tradotto nella propria lingua ti ha motivat* a visitarlo? | E20: x | H20: =IF(C20="X",1)+IF(D20="X",2)+IF(E20="X",3)+IF(F20="X",4)+IF(G20="X",5) -> 3
B21: Personal Control | C21: Scarso | D21: Sufficiente | E21: Buono | F21: Molto Buono | G21: Eccellente | H21: Valore
A22: T6_PC1 | B22: Quanto ti è sembrato semplice e lineare il processo di creazione di un itinerario su misura per le tue esigenze? | F22: x | H22: =IF(C22="X",1)+IF(D22="X",2)+IF(E22="X",3)+IF(F22="X",4)+IF(G22="X",5) -> 4
B23: Motivation
A24: T6_MOT1 | B24: Conoscere un itinerario adatto al proprio viaggio ha influenzato positivamente la pianificazione del proprio viaggio? | G24: x | H24: =IF(C24="X",1)+IF(D24="X",2)+IF(E24="X",3)+IF(F24="X",4)+IF(G24="X",5) -> 5
B25: Motivation | C25: Scarso | D25: Sufficiente | E25: Buono | F25: Molto Buono | G25: Eccellente | H25: Valore
A26: T7_MOT1 | B26: I badge e il sistema di gamification ti ha motivat*? | G26: x | H26: =IF(C26="X",1)+IF(D26="X",2)+IF(E26="X",3)+IF(F26="X",4)+IF(G26="X",5) -> 5
B27: Personal Control | C27: Scarso | D27: Sufficiente | E27: Buono | F27: Molto Buono | G27: Eccellente | H27: Valore
A28: T8_SE1 | B28: In che misura le categorie e i filtri di ricerca proposti dal sistema rispecchiano le tue reali preferenze di viaggio e culturali? | E28: x | H28: =IF(C28="X",1)+IF(D28="X",2)+IF(E28="X",3)+IF(F28="X",4)+IF(G28="X",5) -> 3
B29: Motivation
A30: T8_MOT1 | B30: In che misura le categorie e i filtri di ricerca proposti dal sistema ti hanno motivat*? | F30: x | H30: =IF(C30="X",1)+IF(D30="X",2)+IF(E30="X",3)+IF(F30="X",4)+IF(G30="X",5) -> 4
B31: Motivation | C31: Scarso | D31: Sufficiente | E31: Buono | F31: Molto Buono | G31: Eccellente | H31: Valore
A32: T9_MOT1 | B32: Quanto ritieni che il sistema ti abbia aiutato a scoprire curiosità o approfondimenti storici/culturali sul territorio che prima non conoscevi? | E32: x | H32: =IF(C32="X",1)+IF(D32="X",2)+IF(E32="X",3)+IF(F32="X",4)+IF(G32="X",5) -> 3
B33: Knowledge&Skills | C33: Scarso | D33: Sufficiente | E33: Buono | F33: Molto Buono | G33: Eccellente | H33: Valore
A34: T10_KS1 | B34: Al termine dell'utilizzo del sistema, ti senti sufficientemente informato/a da poterti orientare nel territorio o consigliare la visita a qualcun altro? | G34: x | H34: =IF(C34="X",1)+IF(D34="X",2)+IF(E34="X",3)+IF(F34="X",4)+IF(G34="X",5) -> 5
B35: Motivation
A36: T10_MOT1 | B36: In che modo il suggerimento di un itinerario da altri utenti ha influenzato le tue visite? | F36: x | H36: =IF(C36="X",1)+IF(D36="X",2)+IF(E36="X",3)+IF(F36="X",4)+IF(G36="X",5) -> 4

Sheet Questionario #8
A1: Questionario # | B1: Self Efficacy | C1: Scarso | D1: Sufficiente | E1: Buono | F1: Molto Buono | G1: Eccellente | H1: Valore
A2: T1_SE1 | B2: Quanto hai trovato chiaro e immediato reperire le informazioni pratiche di un punto di interesse (orari di apertura, prezzi o modalità di acquisto biglietti)? | F2: x | H2: =IF(C2="X",1)+IF(D2="X",2)+IF(E2="X",3)+IF(F2="X",4)+IF(G2="X",5) -> 4
B3: Personal Control
A4: T1_PC1 | B4: Quanto hai trovato facile pianificare e concordare le proprie visite consultando gli orari forniti dal sistema? | F4: x | H4: =IF(C4="X",1)+IF(D4="X",2)+IF(E4="X",3)+IF(F4="X",4)+IF(G4="X",5) -> 4
B5: Personal Control | C5: Scarso | D5: Sufficiente | E5: Buono | F5: Molto Buono | G5: Eccellente | H5: Valore
A6: T2_PC1 | B6: Quanto hai trovato facile ottenere informazioni sui prezzi dei biglietti e sulle biglietterie ufficiali? | F6: x | H6: =IF(C6="X",1)+IF(D6="X",2)+IF(E6="X",3)+IF(F6="X",4)+IF(G6="X",5) -> 4
B7: Self Efficacy | C7: Scarso | D7: Sufficiente | E7: Buono | F7: Molto Buono | G7: Eccellente | H7: Valore
A8: T3_SE1 | B8: Quanto sono risultate chiare, complete e leggibili le informazioni generali e le descrizioni dei luoghi proposti? | F8: x | H8: =IF(C8="X",1)+IF(D8="X",2)+IF(E8="X",3)+IF(F8="X",4)+IF(G8="X",5) -> 4
B9: Self Efficacy | C9: Scarso | D9: Sufficiente | E9: Buono | F9: Molto Buono | G9: Eccellente | H9: Valore
A10: T4_SE1 | B10: Le informazioni sull'accessibilità dei siti (es. barriere architettoniche, percorsi dedicati) ti hanno permesso di organizzare la visita in modo più consapevole e agevole? | G10: x | H10: =IF(C10="X",1)+IF(D10="X",2)+IF(E10="X",3)+IF(F10="X",4)+IF(G10="X",5) -> 5
B11: Knowledge&Skills
A12: T4_KS1 | B12: Le informazioni sull'accessibilità dei siti (es. barriere architettoniche, percorsi dedicati) sono sufficienti per chi è portatore di handicap? | F12: x | H12: =IF(C12="X",1)+IF(D12="X",2)+IF(E12="X",3)+IF(F12="X",4)+IF(G12="X",5) -> 4
B13: Personal Control
A14: T4_PC1 | B14: Le informazioni sull'accessibilità dei siti (es. barriere architettoniche, percorsi dedicati) hanno influenzato positivamente le tue decisioni sulle visite ai punti di interesse? | G14: x | H14: =IF(C14="X",1)+IF(D14="X",2)+IF(E14="X",3)+IF(F14="X",4)+IF(G14="X",5) -> 5
B15: Self Efficacy | C15: Scarso | D15: Sufficiente | E15: Buono | F15: Molto Buono | G15: Eccellente | H15: Valore
A16: T5_SE1 | B16: Quanto sono chiare e complete le informazioni tradotte nella propria lingua? | F16: x | H16: =IF(C16="X",1)+IF(D16="X",2)+IF(E16="X",3)+IF(F16="X",4)+IF(G16="X",5) -> 4
B17: Personal Control
A18: T5_PC1 | B18: Le traduzioni disponibili hanno influenzato positivamente le tue decisioni sulle visite ai punti di interesse? | G18: x | H18: =IF(C18="X",1)+IF(D18="X",2)+IF(E18="X",3)+IF(F18="X",4)+IF(G18="X",5) -> 5
B19: Motivation
A20: T5_MOT1 | B20: Conoscere le curiosità di un punto di interesse tradotto nella propria lingua ti ha motivat* a visitarlo? | G20: x | H20: =IF(C20="X",1)+IF(D20="X",2)+IF(E20="X",3)+IF(F20="X",4)+IF(G20="X",5) -> 5
B21: Personal Control | C21: Scarso | D21: Sufficiente | E21: Buono | F21: Molto Buono | G21: Eccellente | H21: Valore
A22: T6_PC1 | B22: Quanto ti è sembrato semplice e lineare il processo di creazione di un itinerario su misura per le tue esigenze? | F22: x | H22: =IF(C22="X",1)+IF(D22="X",2)+IF(E22="X",3)+IF(F22="X",4)+IF(G22="X",5) -> 4
B23: Motivation
A24: T6_MOT1 | B24: Conoscere un itinerario adatto al proprio viaggio ha influenzato positivamente la pianificazione del proprio viaggio? | F24: x | H24: =IF(C24="X",1)+IF(D24="X",2)+IF(E24="X",3)+IF(F24="X",4)+IF(G24="X",5) -> 4
B25: Motivation | C25: Scarso | D25: Sufficiente | E25: Buono | F25: Molto Buono | G25: Eccellente | H25: Valore
A26: T7_MOT1 | B26: I badge e il sistema di gamification ti ha motivat*? | G26: x | H26: =IF(C26="X",1)+IF(D26="X",2)+IF(E26="X",3)+IF(F26="X",4)+IF(G26="X",5) -> 5
B27: Personal Control | C27: Scarso | D27: Sufficiente | E27: Buono | F27: Molto Buono | G27: Eccellente | H27: Valore
A28: T8_SE1 | B28: In che misura le categorie e i filtri di ricerca proposti dal sistema rispecchiano le tue reali preferenze di viaggio e culturali? | G28: x | H28: =IF(C28="X",1)+IF(D28="X",2)+IF(E28="X",3)+IF(F28="X",4)+IF(G28="X",5) -> 5
B29: Motivation
A30: T8_MOT1 | B30: In che misura le categorie e i filtri di ricerca proposti dal sistema ti hanno motivat*? | F30: x | H30: =IF(C30="X",1)+IF(D30="X",2)+IF(E30="X",3)+IF(F30="X",4)+IF(G30="X",5) -> 4
B31: Motivation | C31: Scarso | D31: Sufficiente | E31: Buono | F31: Molto Buono | G31: Eccellente | H31: Valore
A32: T9_MOT1 | B32: Quanto ritieni che il sistema ti abbia aiutato a scoprire curiosità o approfondimenti storici/culturali sul territorio che prima non conoscevi? | F32: x | H32: =IF(C32="X",1)+IF(D32="X",2)+IF(E32="X",3)+IF(F32="X",4)+IF(G32="X",5) -> 4
B33: Knowledge&Skills | C33: Scarso | D33: Sufficiente | E33: Buono | F33: Molto Buono | G33: Eccellente | H33: Valore
A34: T10_KS1 | B34: Al termine dell'utilizzo del sistema, ti senti sufficientemente informato/a da poterti orientare nel territorio o consigliare la visita a qualcun altro? | E34: x | H34: =IF(C34="X",1)+IF(D34="X",2)+IF(E34="X",3)+IF(F34="X",4)+IF(G34="X",5) -> 3
B35: Motivation
A36: T10_MOT1 | B36: In che modo il suggerimento di un itinerario da altri utenti ha influenzato le tue visite? | F36: x | H36: =IF(C36="X",1)+IF(D36="X",2)+IF(E36="X",3)+IF(F36="X",4)+IF(G36="X",5) -> 4

Sheet Questionario #9
B1: Self Efficacy | C1: Scarso | D1: Sufficiente | E1: Buono | F1: Molto Buono | G1: Eccellente | H1: Valore
A2: T1_SE1 | B2: Quanto hai trovato chiaro e immediato reperire le informazioni pratiche di un punto di interesse (orari di apertura, prezzi o modalità di acquisto biglietti)? | G2: x | H2: =IF(C2="X",1)+IF(D2="X",2)+IF(E2="X",3)+IF(F2="X",4)+IF(G2="X",5) -> 5
B3: Personal Control
A4: T1_PC1 | B4: Quanto hai trovato facile pianificare e concordare le proprie visite consultando gli orari forniti dal sistema? | G4: x | H4: =IF(C4="X",1)+IF(D4="X",2)+IF(E4="X",3)+IF(F4="X",4)+IF(G4="X",5) -> 5
B5: Personal Control | C5: Scarso | D5: Sufficiente | E5: Buono | F5: Molto Buono | G5: Eccellente | H5: Valore
A6: T2_PC1 | B6: Quanto hai trovato facile ottenere informazioni sui prezzi dei biglietti e sulle biglietterie ufficiali? | G6: x | H6: =IF(C6="X",1)+IF(D6="X",2)+IF(E6="X",3)+IF(F6="X",4)+IF(G6="X",5) -> 5
