Workbook

Sheet Behaviourability
A1: # | B1: Tasks | C1: Decision Making | D1: Self-Management | E1: Communication | F1: Engagement
A2: 1 | B2: Consultare gli orari ufficiali | C2: PC | D2: SE
A3: 2 | B3: Controllare la disponibilità dei biglietti ed i loro prezzi | C3: PC
A4: 3 | B4: Consultare le informazioni generali | D4: SE
A5: 4 | B5: Ottenere informazioni sull'accessibilità del sito | C5: SE | D5: PC, K&S
A6: 5 | B6: Traduzione in tempo reale | D6: PC | E6: SE | F6: MOT
A7: 6 | B7: Creazione e condivisione di itinerari | D7: PC | F7: MOT
A8: 7 | B8: Visualizzazione dei badge distintivi ottenuti e del livello di turista | F8: MOT
A9: 8 | B9: Filtrare siti per preferenze | D9: PC, MOT
A10: 9 | B10: Approfondire informazioni | F10: MOT
A11: 10 | B11: Consiglire una visita a un sito | E11: K&S | F11: MOT
B13: Legenda
B14: SE = Self-Efficacy
B15: K&S = Knowledge & Skills
B16: PC = Personal Control
B17: MOT = Motivation

Sheet Tabella dei risultati
A1: # | B1: Tasks | C1: ASE | D1: AKS | E1: APC | F1: AMOT
A2: 1 | B2: Consultare gli orari ufficiali | C2: =AVERAGE('Medie delle risposte'!C2:C4) -> 2.7333333 | D2: - | E2: =AVERAGE('Medie delle risposte'!C6:C7) -> 3 | F2: -
A3: 2 | B3: Controllare la disponibilità dei biglietti ed i loro prezzi | C3: - | D3: - | E3: =AVERAGE('Medie delle risposte'!C9:C11) -> 2.8 | F3: -
A4: 3 | B4: Consultare le informazioni generali | C4: =AVERAGE('Medie delle risposte'!C13:C15) -> 2.6 | D4: - | E4: - | F4: -
A5: 4 | B5: Ottenere informazioni sull'accessibilità del sito | C5: =AVERAGE('Medie delle risposte'!C17:C18) -> 2.7 | D5: =AVERAGE('Medie delle risposte'!C20:C21) -> 3.4 | E5: =AVERAGE('Medie delle risposte'!C23:C24) -> 3.1 | F5: -
A6: 5 | B6: Traduzione in tempo reale | C6: =AVERAGE('Medie delle risposte'!C26:C27) -> 2.5 | D6: - | E6: =AVERAGE('Medie delle risposte'!C29:C30) -> 1.7 | F6: =AVERAGE('Medie delle risposte'!C32) -> 1.8
A7: 6 | B7: Creazione e condivisione di itinerari | C7: - | D7: - | E7: =AVERAGE('Medie delle risposte'!C34:C35) -> 3.2 | F7: =AVERAGE('Medie delle risposte'!C37:C38) -> 3
A8: 7 | B8: Visualizzazione dei badge distintivi ottenuti e del livello di turista | C8: - | D8: - | E8: - | F8: =AVERAGE('Medie delle risposte'!C40:C41) -> 2.7
A9: 8 | B9: Filtrare siti per preferenze | C9: - | D9: - | E9: =AVERAGE('Medie delle risposte'!C43:C44) -> 3.7 | F9: =AVERAGE('Medie delle risposte'!C46) -> 2.2
A10: 9 | B10: Approfondire informazioni | C10: - | D10: - | E10: - | F10: =AVERAGE('Medie delle risposte'!C48:C49) -> 2.8
A11: 10 | B11: Consiglire una visita a un sito | C11: - | D11: =AVERAGE('Medie delle risposte'!C51) -> 3.2 | E11: - | F11: =AVERAGE('Medie delle risposte'!C53:C54) -> 3.2
B13: Legenda
B14: ASE = Average Self-Efficacy
B15: AKS = Average Knowledge & Skills
B16: APC = Average Personal Control
B17: AMOT = Average Motivation

Sheet Medie delle risposte
B1: Self Efficacy | C1: Valore
A2: T1_SE1 | B2: In che modo hai consultato gli orari ufficiali del sito? | C2: =AVERAGE('Questionario #1'!H2,'Questionario #2'!H2,'Questionario #3'!H2,'Questionario #4'!H2,'Questionario #5'!H2) -> 3
A3: T1_SE2 | B3: Quanto hai trovato facile reperire le informazioni sugli orari? | C3: =AVERAGE('Questionario #1'!H3,'Questionario #2'!H3,'Questionario #3'!H3,'Questionario #4'!H3,'Questionario #5'!H3) -> 2.4
A4: T1_SE3 | B4: Le informazioni che hai trovato risultavano coerenti con gli orari effettivi del sito? | C4: =AVERAGE('Questionario #1'!H4,'Questionario #2'!H4,'Questionario #3'!H4,'Questionario #4'!H4,'Questionario #5'!H4) -> 2.8
B5: Personal Control | C5: Valore
A6: T1_PC1 | B6: In che modo riesci a pianificare, in maniera efficace e ottimizzando il tempo, il tuo viaggio consultando gli orari ufficiali? | C6: =AVERAGE('Questionario #1'!H6,'Questionario #2'!H6,'Questionario #3'!H6,'Questionario #4'!H6,'Questionario #5'!H6) -> 2.6
A7: T1_PC2 | B7: Quanto hai trovato facile concordare l'orario di visita con l'orario di apertura del sito? | C7: =AVERAGE('Questionario #1'!H7,'Questionario #2'!H7,'Questionario #3'!H7,'Questionario #4'!H7,'Questionario #5'!H7) -> 3.4
B8: Personal Control | C8: Valore
A9: T2_PC1 | B9: Quanto hai trovato facile reperire informazioni sulla disponibilità dei biglietti ed i loro prezzi? | C9: =AVERAGE('Questionario #1'!H9,'Questionario #2'!H9,'Questionario #3'!H9,'Questionario #4'!H9,'Questionario #5'!H9) -> 2.8
A10: T2_PC2 | B10: In che modo sei riuscito a pianificare l'acquisto dei biglietti? | C10: =AVERAGE('Questionario #1'!H10,'Questionario #2'!H10,'Questionario #3'!H10,'Questionario #4'!H10,'Questionario #5'!H10) -> 2.4
A11: T2_PC3 | B11: Quanto hai trovato facile capire se i biglietti per un determinato sito possono essere acquistati online? | C11: =AVERAGE('Questionario #1'!H11,'Questionario #2'!H11,'Questionario #3'!H11,'Questionario #4'!H11,'Questionario #5'!H11) -> 3.2
B12: Self Efficacy | C12: Valore
A13: T3_SE1 | B13: In che modo sei riuscito a reperire le informazioni in maniera dettagliata? | C13: =AVERAGE('Questionario #1'!H13,'Questionario #2'!H13,'Questionario #3'!H13,'Questionario #4'!H13,'Questionario #5'!H13) -> 2.4
A14: T3_SE2 | B14: In che modo hai trovato ciò che ti interessa? | C14: =AVERAGE('Questionario #1'!H14,'Questionario #2'!H14,'Questionario #3'!H14,'Questionario #4'!H14,'Questionario #5'!H14) -> 3.2
A15: T3_SE3 | B15: Le informazioni fornite risultano essere... | C15: =AVERAGE('Questionario #1'!H15,'Questionario #2'!H15,'Questionario #3'!H15,'Questionario #4'!H15,'Questionario #5'!H15) -> 2.2
B16: Self Efficacy | C16: Valore
A17: T4_SE1 | B17: Conoscere l'accessibilità del sito ti ha permesso di creare un itinerario migliore? Se si, come ti è sembrato? | C17: =AVERAGE('Questionario #1'!H17,'Questionario #2'!H17,'Questionario #3'!H17,'Questionario #4'!H17,'Questionario #5'!H17) -> 2.4
A18: T4_SE2 | B18: Le informazioni sulle misure di accessibilità avvisano se il sito è visitabile da solo o è necessario/suggerito un accompagnatore? | C18: =AVERAGE('Questionario #1'!H18,'Questionario #2'!H18,'Questionario #3'!H18,'Questionario #4'!H18,'Questionario #5'!H18) -> 3
B19: Knowledge&Skills | C19: Valore
A20: T4_KS1 | B20: Le informazioni sulle misure di accessibilità sono sufficienti per chi è portatore di handicap? | C20: =AVERAGE('Questionario #1'!H20,'Questionario #2'!H20,'Questionario #3'!H20,'Questionario #4'!H20,'Questionario #5'!H20) -> 3.8
A21: T4_KS2 | B21: Le informazioni sulle misure di accessibilità informano sul tipo di misure adottate e sui supporti disponibili? | C21: =AVERAGE('Questionario #1'!H21,'Questionario #2'!H21,'Questionario #3'!H21,'Questionario #4'!H21,'Questionario #5'!H21) -> 3
B22: Personal Control | C22: Valore
A23: T4_PC1 | B23: Le informazioni sulle misure di accessibilità al sito ha influenzato le tue decisioni? | C23: =AVERAGE('Questionario #1'!H23,'Questionario #2'!H23,'Questionario #3'!H23,'Questionario #4'!H23,'Questionario #5'!H23) -> 3.2
A24: T4_PC2 | B24: Quanto hai trovato facile pianificare una visita dalle informazioni sulle misure di accessibilità trovate? | C24: =AVERAGE('Questionario #1'!H24,'Questionario #2'!H24,'Questionario #3'!H24,'Questionario #4'!H24,'Questionario #5'!H24) -> 3
B25: Self Efficacy | C25: Valore
A26: T5_SE1 | B26: Quanto sono chiare le informazioni tradotte nella tua lingua? | C26: =AVERAGE('Questionario #1'!H26,'Questionario #2'!H26,'Questionario #3'!H26,'Questionario #4'!H26,'Questionario #5'!H26) -> 2.6
A27: T5_SE2 | B27: Quanto sono complete le informazioni tradotte nella tua lingua? | C27: =AVERAGE('Questionario #1'!H27,'Questionario #2'!H27,'Questionario #3'!H27,'Questionario #4'!H27,'Questionario #5'!H27) -> 2.4
B28: Personal Control | C28: Valore
A29: T5_PC1 | B29: Le traduzioni disponibili hanno influenzato le tue decisioni? | C29: =AVERAGE('Questionario #1'!H29,'Questionario #2'!H29,'Questionario #3'!H29,'Questionario #4'!H29,'Questionario #5'!H29) -> 1.6
A30: T5_PC2 | B30: Quanto hai trovato facile pianificare una visita dalle informazioni sulle traduzioni disponoibili? | C30: =AVERAGE('Questionario #1'!H30,'Questionario #2'!H30,'Questionario #3'!H30,'Questionario #4'!H30,'Questionario #5'!H30) -> 1.8
B31: Motivation | C31: Valore
A32: T5_MOT1 | B32: Come conoscere le curiosità di un sito nella tua lingua ti ha motivato visitarlo? | C32: =AVERAGE('Questionario #1'!H32,'Questionario #2'!H32,'Questionario #3'!H32,'Questionario #4'!H32,'Questionario #5'!H32) -> 1.8
B33: Personal Control | C33: Valore
A34: T6_PC1 | B34: Quanto le tue conoscenze hanno influenzato la creazione di nuovi itinerari? | C34: =AVERAGE('Questionario #1'!H34,'Questionario #2'!H34,'Questionario #3'!H34,'Questionario #4'!H34,'Questionario #5'!H34) -> 3.2
A35: T6_PC2 | B35: Quanto hai trovato facile informarsi sulle conoscenze necessarie alla creazione di nuovi itinerari? | C35: =AVERAGE('Questionario #1'!H35,'Questionario #2'!H35,'Questionario #3'!H35,'Questionario #4'!H35,'Questionario #5'!H35) -> 3.2
B36: Motivation | C36: Valore
A37: T6_MOT1 | B37: Quanto ha influenzato la pianificazione del tuo viaggio conoscere un particolare itinerario? | C37: =AVERAGE('Questionario #1'!H37,'Questionario #2'!H37,'Questionario #3'!H37,'Questionario #4'!H37,'Questionario #5'!H37) -> 3.2
A38: T6_MOT2 | B38: Gli itinerari condivisi sono soddisfacenti? | C38: =AVERAGE('Questionario #1'!H38,'Questionario #2'!H38,'Questionario #3'!H38,'Questionario #4'!H38,'Questionario #5'!H38) -> 2.8
B39: Motivation | C39: Valore
A40: T7_MOT1 | B40: I badge ottenuti dai diversi utenti, ti hanno motivato nella scelta di un determinato itinerario o di un determinato sito? | C40: =AVERAGE('Questionario #1'!H40,'Questionario #2'!H40,'Questionario #3'!H40,'Questionario #4'!H40,'Questionario #5'!H40) -> 2.6
...

Sheet Questionario base
B1: Self Efficacy | C1: Scarso | D1: Sufficiente | E1: Buono | F1: Molto Buono | G1: Eccellente | H1: Valore
A2: T1_SE1 | B2: In che modo hai consultato gli orari ufficiali del sito? | H2: =IF(C2="X",1)+IF(D2="X",2)+IF(E2="X",3)+IF(F2="X",4)+IF(G2="X",5) -> 0
A3: T1_SE2 | B3: Quanto hai trovato facile reperire le informazioni sugli orari? | H3: =IF(C3="X",1)+IF(D3="X",2)+IF(E3="X",3)+IF(F3="X",4)+IF(G3="X",5) -> 0
A4: T1_SE3 | B4: Le informazioni che hai trovato risultavano coerenti con gli orari effettivi del sito? | H4: =IF(C4="X",1)+IF(D4="X",2)+IF(E4="X",3)+IF(F4="X",4)+IF(G4="X",5) -> 0
B5: Personal Control
A6: T1_PC1 | B6: In che modo riesci a pianificare, in maniera efficace e ottimizzando il tempo, il tuo viaggio consultando gli orari ufficiali? | H6: =IF(C6="X",1)+IF(D6="X",2)+IF(E6="X",3)+IF(F6="X",4)+IF(G6="X",5) -> 0
A7: T1_PC2 | B7: Quanto hai trovato facile concordare l'orario di visita con l'orario di apertura del sito? | H7: =IF(C7="X",1)+IF(D7="X",2)+IF(E7="X",3)+IF(F7="X",4)+IF(G7="X",5) -> 0
B8: Personal Control | C8: Scarso | D8: Sufficiente | E8: Buono | F8: Molto Buono | G8: Eccellente | H8: Valore
A9: T2_PC1 | B9: Quanto hai trovato facile reperire informazioni sulla disponibilità dei biglietti ed i loro prezzi? | H9: =IF(C9="X",1)+IF(D9="X",2)+IF(E9="X",3)+IF(F9="X",4)+IF(G9="X",5) -> 0
A10: T2_PC2 | B10: In che modo sei riuscito a pianificare l'acquisto dei biglietti? | H10: =IF(C10="X",1)+IF(D10="X",2)+IF(E10="X",3)+IF(F10="X",4)+IF(G10="X",5) -> 0
A11: T2_PC3 | B11: Quanto hai trovato facile capire se i biglietti per un determinato sito possono essere acquistati online? | H11: =IF(C11="X",1)+IF(D11="X",2)+IF(E11="X",3)+IF(F11="X",4)+IF(G11="X",5) -> 0
B12: Self Efficacy | C12: Scarso | D12: Sufficiente | E12: Buono | F12: Molto Buono | G12: Eccellente | H12: Valore
A13: T3_SE1 | B13: In che modo sei riuscito a reperire le informazioni in maniera dettagliata? | H13: =IF(C13="X",1)+IF(D13="X",2)+IF(E13="X",3)+IF(F13="X",4)+IF(G13="X",5) -> 0
A14: T3_SE2 | B14: In che modo hai trovato ciò che ti interessa? | H14: =IF(C14="X",1)+IF(D14="X",2)+IF(E14="X",3)+IF(F14="X",4)+IF(G14="X",5) -> 0
A15: T3_SE3 | B15: Le informazioni fornite risultano essere... | H15: =IF(C15="X",1)+IF(D15="X",2)+IF(E15="X",3)+IF(F15="X",4)+IF(G15="X",5) -> 0
B16: Self Efficacy | C16: Scarso | D16: Sufficiente | E16: Buono | F16: Molto Buono | G16: Eccellente | H16: Valore
A17: T4_SE1 | B17: Conoscere l'accessibilità del sito ti ha permesso di creare un itinerario migliore? Se si, come ti è sembrato? | H17: =IF(C17="X",1)+IF(D17="X",2)+IF(E17="X",3)+IF(F17="X",4)+IF(G17="X",5) -> 0
A18: T4_SE2 | B18: Le informazioni sulle misure di accessibilità avvisano se il sito è visitabile da solo o è necessario/suggerito un accompagnatore? | H18: =IF(C18="X",1)+IF(D18="X",2)+IF(E18="X",3)+IF(F18="X",4)+IF(G18="X",5) -> 0
B19: Knowledge&Skills
A20: T4_KS1 | B20: Le informazioni sulle misure di accessibilità sono sufficienti per chi è portatore di handicap? | H20: =IF(C20="X",1)+IF(D20="X",2)+IF(E20="X",3)+IF(F20="X",4)+IF(G20="X",5) -> 0
A21: T4_KS2 | B21: Le informazioni sulle misure di accessibilità informano sul tipo di misure adottate e sui supporti disponibili? | H21: =IF(C21="X",1)+IF(D21="X",2)+IF(E21="X",3)+IF(F21="X",4)+IF(G21="X",5) -> 0
B22: Personal Control
A23: T4_PC1 | B23: Le informazioni sulle misure di accessibilità al sito ha influenzato le tue decisioni? | H23: =IF(C23="X",1)+IF(D23="X",2)+IF(E23="X",3)+IF(F23="X",4)+IF(G23="X",5) -> 0
A24: T4_PC2 | B24: Quanto hai trovato facile pianificare una visita dalle informazioni sulle misure di accessibilità trovate? | H24: =IF(C24="X",1)+IF(D24="X",2)+IF(E24="X",3)+IF(F24="X",4)+IF(G24="X",5) -> 0
B25: Self Efficacy | C25: Scarso | D25: Sufficiente | E25: Buono | F25: Molto Buono | G25: Eccellente | H25: Valore
A26: T5_SE1 | B26: Quanto sono chiare le informazioni tradotte nella tua lingua? | H26: =IF(C26="X",1)+IF(D26="X",2)+IF(E26="X",3)+IF(F26="X",4)+IF(G26="X",5) -> 0
A27: T5_SE2 | B27: Quanto sono complete le informazioni tradotte nella tua lingua? | H27: =IF(C27="X",1)+IF(D27="X",2)+IF(E27="X",3)+IF(F27="X",4)+IF(G27="X",5) -> 0
B28: Personal Control
A29: T5_PC1 | B29: Le traduzioni disponibili hanno influenzato le tue decisioni? | H29: =IF(C29="X",1)+IF(D29="X",2)+IF(E29="X",3)+IF(F29="X",4)+IF(G29="X",5) -> 0
A30: T5_PC2 | B30: Quanto hai trovato facile pianificare una visita dalle informazioni sulle traduzioni disponoibili? | H30: =IF(C30="X",1)+IF(D30="X",2)+IF(E30="X",3)+IF(F30="X",4)+IF(G30="X",5) -> 0
B31: Motivation
A32: T5_MOT1 | B32: Come conoscere le curiosità di un sito nella tua lingua ti ha motivato visitarlo? | H32: =IF(C32="X",1)+IF(D32="X",2)+IF(E32="X",3)+IF(F32="X",4)+IF(G32="X",5) -> 0
B33: Personal Control | C33: Scarso | D33: Sufficiente | E33: Buono | F33: Molto Buono | G33: Eccellente | H33: Valore
A34: T6_PC1 | B34: Quanto le tue conoscenze hanno influenzato la creazione di nuovi itinerari? | H34: =IF(C34="X",1)+IF(D34="X",2)+IF(E34="X",3)+IF(F34="X",4)+IF(G34="X",5) -> 0
A35: T6_PC2 | B35: Quanto hai trovato facile informarsi sulle conoscenze necessarie alla creazione di nuovi itinerari? | H35: =IF(C35="X",1)+IF(D35="X",2)+IF(E35="X",3)+IF(F35="X",4)+IF(G35="X",5) -> 0
B36: Motivation
A37: T6_MOT1 | B37: Quanto ha influenzato la pianificazione del tuo viaggio conoscere un particolare itinerario? | H37: =IF(C37="X",1)+IF(D37="X",2)+IF(E37="X",3)+IF(F37="X",4)+IF(G37="X",5) -> 0
A38: T6_MOT2 | B38: Gli itinerari condivisi sono soddisfacenti? | H38: =IF(C38="X",1)+IF(D38="X",2)+IF(E38="X",3)+IF(F38="X",4)+IF(G38="X",5) -> 0
B39: Motivation | C39: Scarso | D39: Sufficiente | E39: Buono | F39: Molto Buono | G39: Eccellente | H39: Valore
A40: T7_MOT1 | B40: I badge ottenuti dai diversi utenti, ti hanno motivato nella scelta di un determinato itinerario o di un determinato sito? | H40: =IF(C40="X",1)+IF(D40="X",2)+IF(E40="X",3)+IF(F40="X",4)+IF(G40="X",5) -> 0
...

Sheet Questionario #1
B1: Self Efficacy | C1: Scarso | D1: Sufficiente | E1: Buono | F1: Molto Buono | G1: Eccellente | H1: Valore
A2: T1_SE1 | B2: In che modo hai consultato gli orari ufficiali del sito? | E2: x | H2: =IF(C2="X",1)+IF(D2="X",2)+IF(E2="X",3)+IF(F2="X",4)+IF(G2="X",5) -> 3
A3: T1_SE2 | B3: Quanto hai trovato facile reperire le informazioni sugli orari? | E3: x | H3: =IF(C3="X",1)+IF(D3="X",2)+IF(E3="X",3)+IF(F3="X",4)+IF(G3="X",5) -> 3
A4: T1_SE3 | B4: Le informazioni che hai trovato risultavano coerenti con gli orari effettivi del sito? | F4: x | H4: =IF(C4="X",1)+IF(D4="X",2)+IF(E4="X",3)+IF(F4="X",4)+IF(G4="X",5) -> 4
B5: Personal Control
A6: T1_PC1 | B6: In che modo riesci a pianificare, in maniera efficace e ottimizzando il tempo, il tuo viaggio consultando gli orari ufficiali? | F6: x | H6: =IF(C6="X",1)+IF(D6="X",2)+IF(E6="X",3)+IF(F6="X",4)+IF(G6="X",5) -> 4
A7: T1_PC2 | B7: Quanto hai trovato facile concordare l'orario di visita con l'orario di apertura del sito? | F7: x | H7: =IF(C7="X",1)+IF(D7="X",2)+IF(E7="X",3)+IF(F7="X",4)+IF(G7="X",5) -> 4
B8: Personal Control | C8: Scarso | D8: Sufficiente | E8: Buono | F8: Molto Buono | G8: Eccellente | H8: Valore
A9: T2_PC1 | B9: Quanto hai trovato facile reperire informazioni sulla disponibilità dei biglietti ed i loro prezzi? | D9: x | H9: =IF(C9="X",1)+IF(D9="X",2)+IF(E9="X",3)+IF(F9="X",4)+IF(G9="X",5) -> 2
A10: T2_PC2 | B10: In che modo sei riuscito a pianificare l'acquisto dei biglietti? | D10: x | H10: =IF(C10="X",1)+IF(D10="X",2)+IF(E10="X",3)+IF(F10="X",4)+IF(G10="X",5) -> 2
A11: T2_PC3 | B11: Quanto hai trovato facile capire se i biglietti per un determinato sito possono essere acquistati online? | D11: x | H11: =IF(C11="X",1)+IF(D11="X",2)+IF(E11="X",3)+IF(F11="X",4)+IF(G11="X",5) -> 2
B12: Self Efficacy | C12: Scarso | D12: Sufficiente | E12: Buono | F12: Molto Buono | G12: Eccellente | H12: Valore
A13: T3_SE1 | B13: In che modo sei riuscito a reperire le informazioni in maniera dettagliata? | E13: x | H13: =IF(C13="X",1)+IF(D13="X",2)+IF(E13="X",3)+IF(F13="X",4)+IF(G13="X",5) -> 3
A14: T3_SE2 | B14: In che modo hai trovato ciò che ti interessa? | E14: x | H14: =IF(C14="X",1)+IF(D14="X",2)+IF(E14="X",3)+IF(F14="X",4)+IF(G14="X",5) -> 3
A15: T3_SE3 | B15: Le informazioni fornite risultano essere... | E15: x | H15: =IF(C15="X",1)+IF(D15="X",2)+IF(E15="X",3)+IF(F15="X",4)+IF(G15="X",5) -> 3
B16: Self Efficacy | C16: Scarso | D16: Sufficiente | E16: Buono | F16: Molto Buono | G16: Eccellente | H16: Valore
A17: T4_SE1 | B17: Conoscere l'accessibilità del sito ti ha permesso di creare un itinerario migliore? Se si, come ti è sembrato? | E17: x | H17: =IF(C17="X",1)+IF(D17="X",2)+IF(E17="X",3)+IF(F17="X",4)+IF(G17="X",5) -> 3
A18: T4_SE2 | B18: Le informazioni sulle misure di accessibilità avvisano se il sito è visitabile da solo o è necessario/suggerito un accompagnatore? | E18: x | H18: =IF(C18="X",1)+IF(D18="X",2)+IF(E18="X",3)+IF(F18="X",4)+IF(G18="X",5) -> 3
B19: Knowledge&Skills
A20: T4_KS1 | B20: Le informazioni sulle misure di accessibilità sono sufficienti per chi è portatore di handicap? | E20: x | H20: =IF(C20="X",1)+IF(D20="X",2)+IF(E20="X",3)+IF(F20="X",4)+IF(G20="X",5) -> 3
A21: T4_KS2 | B21: Le informazioni sulle misure di accessibilità informano sul tipo di misure adottate e sui supporti disponibili? | E21: x | H21: =IF(C21="X",1)+IF(D21="X",2)+IF(E21="X",3)+IF(F21="X",4)+IF(G21="X",5) -> 3
B22: Personal Control
A23: T4_PC1 | B23: Le informazioni sulle misure di accessibilità al sito ha influenzato le tue decisioni? | E23: x | H23: =IF(C23="X",1)+IF(D23="X",2)+IF(E23="X",3)+IF(F23="X",4)+IF(G23="X",5) -> 3
A24: T4_PC2 | B24: Quanto hai trovato facile pianificare una visita dalle informazioni sulle misure di accessibilità trovate? | E24: x | H24: =IF(C24="X",1)+IF(D24="X",2)+IF(E24="X",3)+IF(F24="X",4)+IF(G24="X",5) -> 3
B25: Self Efficacy | C25: Scarso | D25: Sufficiente | E25: Buono | F25: Molto Buono | G25: Eccellente | H25: Valore
A26: T5_SE1 | B26: Quanto sono chiare le informazioni tradotte nella tua lingua? | H26: =IF(C26="X",1)+IF(D26="X",2)+IF(E26="X",3)+IF(F26="X",4)+IF(G26="X",5) -> 0
A27: T5_SE2 | B27: Quanto sono complete le informazioni tradotte nella tua lingua? | H27: =IF(C27="X",1)+IF(D27="X",2)+IF(E27="X",3)+IF(F27="X",4)+IF(G27="X",5) -> 0
B28: Personal Control
A29: T5_PC1 | B29: Le traduzioni disponibili hanno influenzato le tue decisioni? | H29: =IF(C29="X",1)+IF(D29="X",2)+IF(E29="X",3)+IF(F29="X",4)+IF(G29="X",5) -> 0
A30: T5_PC2 | B30: Quanto hai trovato facile pianificare una visita dalle informazioni sulle traduzioni disponoibili? | H30: =IF(C30="X",1)+IF(D30="X",2)+IF(E30="X",3)+IF(F30="X",4)+IF(G30="X",5) -> 0
B31: Motivation
A32: T5_MOT1 | B32: Come conoscere le curiosità di un sito nella tua lingua ti ha motivato visitarlo? | H32: =IF(C32="X",1)+IF(D32="X",2)+IF(E32="X",3)+IF(F32="X",4)+IF(G32="X",5) -> 0
B33: Personal Control | G33: Eccellente | H33: Valore
A34: T6_PC1 | B34: Quanto le tue conoscenze hanno influenzato la creazione di nuovi itinerari? | F34: x | H34: =IF(C34="X",1)+IF(D34="X",2)+IF(E34="X",3)+IF(F34="X",4)+IF(G34="X",5) -> 4
A35: T6_PC2 | B35: Quanto hai trovato facile informarsi sulle conoscenze necessarie alla creazione di nuovi itinerari? | F35: x | H35: =IF(C35="X",1)+IF(D35="X",2)+IF(E35="X",3)+IF(F35="X",4)+IF(G35="X",5) -> 4
B36: Motivation
A37: T6_MOT1 | B37: Quanto ha influenzato la pianificazione del tuo viaggio conoscere un particolare itinerario? | E37: x | H37: =IF(C37="X",1)+IF(D37="X",2)+IF(E37="X",3)+IF(F37="X",4)+IF(G37="X",5) -> 3
A38: T6_MOT2 | B38: Gli itinerari condivisi sono soddisfacenti? | E38: x | H38: =IF(C38="X",1)+IF(D38="X",2)+IF(E38="X",3)+IF(F38="X",4)+IF(G38="X",5) -> 3
B39: Motivation | C39: Scarso | D39: Sufficiente | E39: Buono | F39: Molto Buono | G39: Eccellente | H39: Valore
A40: T7_MOT1 | B40: I badge ottenuti dai diversi utenti, ti hanno motivato nella scelta di un determinato itinerario o di un determinato sito? | D40: x | H40: =IF(C40="X",1)+IF(D40="X",2)+IF(E40="X",3)+IF(F40="X",4)+IF(G40="X",5) -> 2
...

Sheet Questionario #2
B1: Self Efficacy | C1: Scarso | D1: Sufficiente | E1: Buono | F1: Molto Buono | G1: Eccellente | H1: Valore
A2: T1_SE1 | B2: In che modo hai consultato gli orari ufficiali del sito? | E2: x | H2: =IF(C2="X",1)+IF(D2="X",2)+IF(E2="X",3)+IF(F2="X",4)+IF(G2="X",5) -> 3
A3: T1_SE2 | B3: Quanto hai trovato facile reperire le informazioni sugli orari? | D3: x | H3: =IF(C3="X",1)+IF(D3="X",2)+IF(E3="X",3)+IF(F3="X",4)+IF(G3="X",5) -> 2
A4: T1_SE3 | B4: Le informazioni che hai trovato risultavano coerenti con gli orari effettivi del sito? | F4: x | H4: =IF(C4="X",1)+IF(D4="X",2)+IF(E4="X",3)+IF(F4="X",4)+IF(G4="X",5) -> 4
B5: Personal Control
A6: T1_PC1 | B6: In che modo riesci a pianificare, in maniera efficace e ottimizzando il tempo, il tuo viaggio consultando gli orari ufficiali? | D6: x | H6: =IF(C6="X",1)+IF(D6="X",2)+IF(E6="X",3)+IF(F6="X",4)+IF(G6="X",5) -> 2
A7: T1_PC2 | B7: Quanto hai trovato facile concordare l'orario di visita con l'orario di apertura del sito? | F7: x | H7: =IF(C7="X",1)+IF(D7="X",2)+IF(E7="X",3)+IF(F7="X",4)+IF(G7="X",5) -> 4
B8: Personal Control | C8: Scarso | D8: Sufficiente | E8: Buono | F8: Molto Buono | G8: Eccellente | H8: Valore
A9: T2_PC1 | B9: Quanto hai trovato facile reperire informazioni sulla disponibilità dei biglietti ed i loro prezzi? | E9: x | H9: =IF(C9="X",1)+IF(D9="X",2)+IF(E9="X",3)+IF(F9="X",4)+IF(G9="X",5) -> 3
A10: T2_PC2 | B10: In che modo sei riuscito a pianificare l'acquisto dei biglietti? | D10: x | H10: =IF(C10="X",1)+IF(D10="X",2)+IF(E10="X",3)+IF(F10="X",4)+IF(G10="X",5) -> 2
A11: T2_PC3 | B11: Quanto hai trovato facile capire se i biglietti per un determinato sito possono essere acquistati online? | F11: x | H11: =IF(C11="X",1)+IF(D11="X",2)+IF(E11="X",3)+IF(F11="X",4)+IF(G11="X",5) -> 4
B12: Self Efficacy | C12: Scarso | D12: Sufficiente | E12: Buono | F12: Molto Buono | G12: Eccellente | H12: Valore
A13: T3_SE1 | B13: In che modo sei riuscito a reperire le informazioni in maniera dettagliata? | C13: x | H13: =IF(C13="X",1)+IF(D13="X",2)+IF(E13="X",3)+IF(F13="X",4)+IF(G13="X",5) -> 1
A14: T3_SE2 | B14: In che modo hai trovato ciò che ti interessa? | E14: x | H14: =IF(C14="X",1)+IF(D14="X",2)+IF(E14="X",3)+IF(F14="X",4)+IF(G14="X",5) -> 3
A15: T3_SE3 | B15: Le informazioni fornite risultano essere... | D15: x | H15: =IF(C15="X",1)+IF(D15="X",2)+IF(E15="X",3)+IF(F15="X",4)+IF(G15="X",5) -> 2
B16: Self Efficacy | C16: Scarso | D16: Sufficiente | E16: Buono | F16: Molto Buono | G16: Eccellente | H16: Valore
A17: T4_SE1 | B17: Conoscere l'accessibilità del sito ti ha permesso di creare un itinerario migliore? Se si, come ti è sembrato? | C17: x | H17: =IF(C17="X",1)+IF(D17="X",2)+IF(E17="X",3)+IF(F17="X",4)+IF(G17="X",5) -> 1
A18: T4_SE2 | B18: Le informazioni sulle misure di accessibilità avvisano se il sito è visitabile da solo o è necessario/suggerito un accompagnatore? | D18: x | H18: =IF(C18="X",1)+IF(D18="X",2)+IF(E18="X",3)+IF(F18="X",4)+IF(G18="X",5) -> 2
B19: Knowledge&Skills
A20: T4_KS1 | B20: Le informazioni sulle misure di accessibilità sono sufficienti per chi è portatore di handicap? | E20: x | H20: =IF(C20="X",1)+IF(D20="X",2)+IF(E20="X",3)+IF(F20="X",4)+IF(G20="X",5) -> 3
A21: T4_KS2 | B21: Le informazioni sulle misure di accessibilità informano sul tipo di misure adottate e sui supporti disponibili? | E21: x | H21: =IF(C21="X",1)+IF(D21="X",2)+IF(E21="X",3)+IF(F21="X",4)+IF(G21="X",5) -> 3
B22: Personal Control
A23: T4_PC1 | B23: Le informazioni sulle misure di accessibilità al sito ha influenzato le tue decisioni? | E23: x | H23: =IF(C23="X",1)+IF(D23="X",2)+IF(E23="X",3)+IF(F23="X",4)+IF(G23="X",5) -> 3
A24: T4_PC2 | B24: Quanto hai trovato facile pianificare una visita dalle informazioni sulle misure di accessibilità trovate? | E24: x | H24: =IF(C24="X",1)+IF(D24="X",2)+IF(E24="X",3)+IF(F24="X",4)+IF(G24="X",5) -> 3
B25: Self Efficacy | C25: Scarso | D25: Sufficiente | E25: Buono | F25: Molto Buono | G25: Eccellente | H25: Valore
A26: T5_SE1 | B26: Quanto sono chiare le informazioni tradotte nella tua lingua? | H26: =IF(C26="X",1)+IF(D26="X",2)+IF(E26="X",3)+IF(F26="X",4)+IF(G26="X",5) -> 0
A27: T5_SE2 | B27: Quanto sono complete le informazioni tradotte nella tua lingua? | H27: =IF(C27="X",1)+IF(D27="X",2)+IF(E27="X",3)+IF(F27="X",4)+IF(G27="X",5) -> 0
B28: Personal Control
A29: T5_PC1 | B29: Le traduzioni disponibili hanno influenzato le tue decisioni? | H29: =IF(C29="X",1)+IF(D29="X",2)+IF(E29="X",3)+IF(F29="X",4)+IF(G29="X",5) -> 0
A30: T5_PC2 | B30: Quanto hai trovato facile pianificare una visita dalle informazioni sulle traduzioni disponoibili? | H30: =IF(C30="X",1)+IF(D30="X",2)+IF(E30="X",3)+IF(F30="X",4)+IF(G30="X",5) -> 0
B31: Motivation
A32: T5_MOT1 | B32: Come conoscere le curiosità di un sito nella tua lingua ti ha motivato visitarlo? | H32: =IF(C32="X",1)+IF(D32="X",2)+IF(E32="X",3)+IF(F32="X",4)+IF(G32="X",5) -> 0
B33: Personal Control | G33: Eccellente | H33: Valore
A34: T6_PC1 | B34: Quanto le tue conoscenze hanno influenzato la creazione di nuovi itinerari? | F34: x | H34: =IF(C34="X",1)+IF(D34="X",2)+IF(E34="X",3)+IF(F34="X",4)+IF(G34="X",5) -> 4
A35: T6_PC2 | B35: Quanto hai trovato facile informarsi sulle conoscenze necessarie alla creazione di nuovi itinerari? | F35: x | H35: =IF(C35="X",1)+IF(D35="X",2)+IF(E35="X",3)+IF(F35="X",4)+IF(G35="X",5) -> 4
B36: Motivation
A37: T6_MOT1 | B37: Quanto ha influenzato la pianificazione del tuo viaggio conoscere un particolare itinerario? | E37: x | H37: =IF(C37="X",1)+IF(D37="X",2)+IF(E37="X",3)+IF(F37="X",4)+IF(G37="X",5) -> 3
A38: T6_MOT2 | B38: Gli itinerari condivisi sono soddisfacenti? | E38: x | H38: =IF(C38="X",1)+IF(D38="X",2)+IF(E38="X",3)+IF(F38="X",4)+IF(G38="X",5) -> 3
B39: Motivation | C39: Scarso | D39: Sufficiente | E39: Buono | F39: Molto Buono | G39: Eccellente | H39: Valore
A40: T7_MOT1 | B40: I badge ottenuti dai diversi utenti, ti hanno motivato nella scelta di un determinato itinerario o di un determinato sito? | E40: x | H40: =IF(C40="X",1)+IF(D40="X",2)+IF(E40="X",3)+IF(F40="X",4)+IF(G40="X",5) -> 3
...

Sheet Questionario #3
B1: Self Efficacy | C1: Scarso | D1: Sufficiente | E1: Buono | F1: Molto Buono | G1: Eccellente | H1: Valore
A2: T1_SE1 | B2: In che modo hai consultato gli orari ufficiali del sito? | D2: x | H2: =IF(C2="X",1)+IF(D2="X",2)+IF(E2="X",3)+IF(F2="X",4)+IF(G2="X",5) -> 2
A3: T1_SE2 | B3: Quanto hai trovato facile reperire le informazioni sugli orari? | D3: x | H3: =IF(C3="X",1)+IF(D3="X",2)+IF(E3="X",3)+IF(F3="X",4)+IF(G3="X",5) -> 2
A4: T1_SE3 | B4: Le informazioni che hai trovato risultavano coerenti con gli orari effettivi del sito? | D4: x | H4: =IF(C4="X",1)+IF(D4="X",2)+IF(E4="X",3)+IF(F4="X",4)+IF(G4="X",5) -> 2
B5: Personal Control
A6: T1_PC1 | B6: In che modo riesci a pianificare, in maniera efficace e ottimizzando il tempo, il tuo viaggio consultando gli orari ufficiali? | F6: x | H6: =IF(C6="X",1)+IF(D6="X",2)+IF(E6="X",3)+IF(F6="X",4)+IF(G6="X",5) -> 4
A7: T1_PC2 | B7: Quanto hai trovato facile concordare l'orario di visita con l'orario di apertura del sito? | F7: x | H7: =IF(C7="X",1)+IF(D7="X",2)+IF(E7="X",3)+IF(F7="X",4)+IF(G7="X",5) -> 4
B8: Personal Control | C8: Scarso | D8: Sufficiente | E8: Buono | F8: Molto Buono | G8: Eccellente | H8: Valore
A9: T2_PC1 | B9: Quanto hai trovato facile reperire informazioni sulla disponibilità dei biglietti ed i loro prezzi? | E9: x | H9: =IF(C9="X",1)+IF(D9="X",2)+IF(E9="X",3)+IF(F9="X",4)+IF(G9="X",5) -> 3
A10: T2_PC2 | B10: In che modo sei riuscito a pianificare l'acquisto dei biglietti? | D10: x | H10: =IF(C10="X",1)+IF(D10="X",2)+IF(E10="X",3)+IF(F10="X",4)+IF(G10="X",5) -> 2
A11: T2_PC3 | B11: Quanto hai trovato facile capire se i biglietti per un determinato sito possono essere acquistati online? | F11: x | H11: =IF(C11="X",1)+IF(D11="X",2)+IF(E11="X",3)+IF(F11="X",4)+IF(G11="X",5) -> 4
B12: Self Efficacy | C12: Scarso | D12: Sufficiente | E12: Buono | F12: Molto Buono | G12: Eccellente | H12: Valore
A13: T3_SE1 | B13: In che modo sei riuscito a reperire le informazioni in maniera dettagliata? | F13: x | H13: =IF(C13="X",1)+IF(D13="X",2)+IF(E13="X",3)+IF(F13="X",4)+IF(G13="X",5) -> 4
A14: T3_SE2 | B14: In che modo hai trovato ciò che ti interessa? | E14: x | H14: =IF(C14="X",1)+IF(D14="X",2)+IF(E14="X",3)+IF(F14="X",4)+IF(G14="X",5) -> 3
A15: T3_SE3 | B15: Le informazioni fornite risultano essere... | D15: x | H15: =IF(C15="X",1)+IF(D15="X",2)+IF(E15="X",3)+IF(F15="X",4)+IF(G15="X",5) -> 2
B16: Self Efficacy | C16: Scarso | D16: Sufficiente | E16: Buono | F16: Molto Buono | G16: Eccellente | H16: Valore
A17: T4_SE1 | B17: Conoscere l'accessibilità del sito ti ha permesso di creare un itinerario migliore? Se si, come ti è sembrato? | E17: x | H17: =IF(C17="X",1)+IF(D17="X",2)+IF(E17="X",3)+IF(F17="X",4)+IF(G17="X",5) -> 3
A18: T4_SE2 | B18: Le informazioni sulle misure di accessibilità avvisano se il sito è visitabile da solo o è necessario/suggerito un accompagnatore? | E18: x | H18: =IF(C18="X",1)+IF(D18="X",2)+IF(E18="X",3)+IF(F18="X",4)+IF(G18="X",5) -> 3
B19: Knowledge&Skills
A20: T4_KS1 | B20: Le informazioni sulle misure di accessibilità sono sufficienti per chi è portatore di handicap? | F20: x | H20: =IF(C20="X",1)+IF(D20="X",2)+IF(E20="X",3)+IF(F20="X",4)+IF(G20="X",5) -> 4
A21: T4_KS2 | B21: Le informazioni sulle misure di accessibilità informano sul tipo di misure adottate e sui supporti disponibili? | E21: x | H21: =IF(C21="X",1)+IF(D21="X",2)+IF(E21="X",3)+IF(F21="X",4)+IF(G21="X",5) -> 3
B22: Personal Control
A23: T4_PC1 | B23: Le informazioni sulle misure di accessibilità al sito ha influenzato le tue decisioni? | E23: x | H23: =IF(C23="X",1)+IF(D23="X",2)+IF(E23="X",3)+IF(F23="X",4)+IF(G23="X",5) -> 3
A24: T4_PC2 | B24: Quanto hai trovato facile pianificare una visita dalle informazioni sulle misure di accessibilità trovate? | D24: x | H24: =IF(C24="X",1)+IF(D24="X",2)+IF(E24="X",3)+IF(F24="X",4)+IF(G24="X",5) -> 2
B25: Self Efficacy | C25: Scarso | D25: Sufficiente | E25: Buono | F25: Molto Buono | G25: Eccellente | H25: Valore
A26: T5_SE1 | B26: Quanto sono chiare le informazioni tradotte nella tua lingua? | F26: x | H26: =IF(C26="X",1)+IF(D26="X",2)+IF(E26="X",3)+IF(F26="X",4)+IF(G26="X",5) -> 4
A27: T5_SE2 | B27: Quanto sono complete le informazioni tradotte nella tua lingua? | F27: x | H27: =IF(C27="X",1)+IF(D27="X",2)+IF(E27="X",3)+IF(F27="X",4)+IF(G27="X",5) -> 4
B28: Personal Control
A29: T5_PC1 | B29: Le traduzioni disponibili hanno influenzato le tue decisioni? | E29: x | H29: =IF(C29="X",1)+IF(D29="X",2)+IF(E29="X",3)+IF(F29="X",4)+IF(G29="X",5) -> 3
A30: T5_PC2 | B30: Quanto hai trovato facile pianificare una visita dalle informazioni sulle traduzioni disponoibili? | C30: x | H30: =IF(C30="X",1)+IF(D30="X",2)+IF(E30="X",3)+IF(F30="X",4)+IF(G30="X",5) -> 1
B31: Motivation
A32: T5_MOT1 | B32: Come conoscere le curiosità di un sito nella tua lingua ti ha motivato visitarlo? | H32: =IF(C32="X",1)+IF(D32="X",2)+IF(E32="X",3)+IF(F32="X",4)+IF(G32="X",5) -> 0
B33: Personal Control | G33: Eccellente | H33: Valore
A34: T6_PC1 | B34: Quanto le tue conoscenze hanno influenzato la creazione di nuovi itinerari? | D34: x | H34: =IF(C34="X",1)+IF(D34="X",2)+IF(E34="X",3)+IF(F34="X",4)+IF(G34="X",5) -> 2
A35: T6_PC2 | B35: Quanto hai trovato facile informarsi sulle conoscenze necessarie alla creazione di nuovi itinerari? | D35: x | H35: =IF(C35="X",1)+IF(D35="X",2)+IF(E35="X",3)+IF(F35="X",4)+IF(G35="X",5) -> 2
B36: Motivation
A37: T6_MOT1 | B37: Quanto ha influenzato la pianificazione del tuo viaggio conoscere un particolare itinerario? | E37: x | H37: =IF(C37="X",1)+IF(D37="X",2)+IF(E37="X",3)+IF(F37="X",4)+IF(G37="X",5) -> 3
A38: T6_MOT2 | B38: Gli itinerari condivisi sono soddisfacenti? | F38: x | H38: =IF(C38="X",1)+IF(D38="X",2)+IF(E38="X",3)+IF(F38="X",4)+IF(G38="X",5) -> 4
B39: Motivation | C39: Scarso | D39: Sufficiente | E39: Buono | F39: Molto Buono | G39: Eccellente | H39: Valore
A40: T7_MOT1 | B40: I badge ottenuti dai diversi utenti, ti hanno motivato nella scelta di un determinato itinerario o di un determinato sito? | D40: x | H40: =IF(C40="X",1)+IF(D40="X",2)+IF(E40="X",3)+IF(F40="X",4)+IF(G40="X",5) -> 2
...

Sheet Questionario #4
B1: Self Efficacy | C1: Scarso | D1: Sufficiente | E1: Buono | F1: Molto Buono | G1: Eccellente | H1: Valore
A2: T1_SE1 | B2: In che modo hai consultato gli orari ufficiali del sito? | F2: x | H2: =IF(C2="X",1)+IF(D2="X",2)+IF(E2="X",3)+IF(F2="X",4)+IF(G2="X",5) -> 4
A3: T1_SE2 | B3: Quanto hai trovato facile reperire le informazioni sugli orari? | E3: x | H3: =IF(C3="X",1)+IF(D3="X",2)+IF(E3="X",3)+IF(F3="X",4)+IF(G3="X",5) -> 3
A4: T1_SE3 | B4: Le informazioni che hai trovato risultavano coerenti con gli orari effettivi del sito? | E4: x | H4: =IF(C4="X",1)+IF(D4="X",2)+IF(E4="X",3)+IF(F4="X",4)+IF(G4="X",5) -> 3
B5: Personal Control
A6: T1_PC1 | B6: In che modo riesci a pianificare, in maniera efficace e ottimizzando il tempo, il tuo viaggio consultando gli orari ufficiali? | D6: x | H6: =IF(C6="X",1)+IF(D6="X",2)+IF(E6="X",3)+IF(F6="X",4)+IF(G6="X",5) -> 2
A7: T1_PC2 | B7: Quanto hai trovato facile concordare l'orario di visita con l'orario di apertura del sito? | F7: x | H7: =IF(C7="X",1)+IF(D7="X",2)+IF(E7="X",3)+IF(F7="X",4)+IF(G7="X",5) -> 4
B8: Personal Control | C8: Scarso | D8: Sufficiente | E8: Buono | F8: Molto Buono | G8: Eccellente | H8: Valore
A9: T2_PC1 | B9: Quanto hai trovato facile reperire informazioni sulla disponibilità dei biglietti ed i loro prezzi? | G9: x | H9: =IF(C9="X",1)+IF(D9="X",2)+IF(E9="X",3)+IF(F9="X",4)+IF(G9="X",5) -> 5
A10: T2_PC2 | B10: In che modo sei riuscito a pianificare l'acquisto dei biglietti? | G10: x | H10: =IF(C10="X",1)+IF(D10="X",2)+IF(E10="X",3)+IF(F10="X",4)+IF(G10="X",5) -> 5
A11: T2_PC3 | B11: Quanto hai trovato facile capire se i biglietti per un determinato sito possono essere acquistati online? | F11: x | H11: =IF(C11="X",1)+IF(D11="X",2)+IF(E11="X",3)+IF(F11="X",4)+IF(G11="X",5) -> 4
B12: Self Efficacy | C12: Scarso | D12: Sufficiente | E12: Buono | F12: Molto Buono | G12: Eccellente | H12: Valore
A13: T3_SE1 | B13: In che modo sei riuscito a reperire le informazioni in maniera dettagliata? | D13: x | H13: =IF(C13="X",1)+IF(D13="X",2)+IF(E13="X",3)+IF(F13="X",4)+IF(G13="X",5) -> 2
A14: T3_SE2 | B14: In che modo hai trovato ciò che ti interessa? | F14: x | H14: =IF(C14="X",1)+IF(D14="X",2)+IF(E14="X",3)+IF(F14="X",4)+IF(G14="X",5) -> 4
A15: T3_SE3 | B15: Le informazioni fornite risultano essere... | D15: x | H15: =IF(C15="X",1)+IF(D15="X",2)+IF(E15="X",3)+IF(F15="X",4)+IF(G15="X",5) -> 2
B16: Self Efficacy | C16: Scarso | D16: Sufficiente | E16: Buono | F16: Molto Buono | G16: Eccellente | H16: Valore
A17: T4_SE1 | B17: Conoscere l'accessibilità del sito ti ha permesso di creare un itinerario migliore? Se si, come ti è sembrato? | E17: x | H17: =IF(C17="X",1)+IF(D17="X",2)+IF(E17="X",3)+IF(F17="X",4)+IF(G17="X",5) -> 3
A18: T4_SE2 | B18: Le informazioni sulle misure di accessibilità avvisano se il sito è visitabile da solo o è necessario/suggerito un accompagnatore? | F18: x | H18: =IF(C18="X",1)+IF(D18="X",2)+IF(E18="X",3)+IF(F18="X",4)+IF(G18="X",5) -> 4
B19: Knowledge&Skills
A20: T4_KS1 | B20: Le informazioni sulle misure di accessibilità sono sufficienti per chi è portatore di handicap? | G20: x | H20: =IF(C20="X",1)+IF(D20="X",2)+IF(E20="X",3)+IF(F20="X",4)+IF(G20="X",5) -> 5
A21: T4_KS2 | B21: Le informazioni sulle misure di accessibilità informano sul tipo di misure adottate e sui supporti disponibili? | G21: x | H21: =IF(C21="X",1)+IF(D21="X",2)+IF(E21="X",3)+IF(F21="X",4)+IF(G21="X",5) -> 5
B22: Personal Control
A23: T4_PC1 | B23: Le informazioni sulle misure di accessibilità al sito ha influenzato le tue decisioni? | F23: x | H23: =IF(C23="X",1)+IF(D23="X",2)+IF(E23="X",3)+IF(F23="X",4)+IF(G23="X",5) -> 4
A24: T4_PC2 | B24: Quanto hai trovato facile pianificare una visita dalle informazioni sulle misure di accessibilità trovate? | F24: x | H24: =IF(C24="X",1)+IF(D24="X",2)+IF(E24="X",3)+IF(F24="X",4)+IF(G24="X",5) -> 4
B25: Self Efficacy | C25: Scarso | D25: Sufficiente | E25: Buono | F25: Molto Buono | G25: Eccellente | H25: Valore
A26: T5_SE1 | B26: Quanto sono chiare le informazioni tradotte nella tua lingua? | G26: x | H26: =IF(C26="X",1)+IF(D26="X",2)+IF(E26="X",3)+IF(F26="X",4)+IF(G26="X",5) -> 5
A27: T5_SE2 | B27: Quanto sono complete le informazioni tradotte nella tua lingua? | F27: x | H27: =IF(C27="X",1)+IF(D27="X",2)+IF(E27="X",3)+IF(F27="X",4)+IF(G27="X",5) -> 4
B28: Personal Control
A29: T5_PC1 | B29: Le traduzioni disponibili hanno influenzato le tue decisioni? | D29: x | H29: =IF(C29="X",1)+IF(D29="X",2)+IF(E29="X",3)+IF(F29="X",4)+IF(G29="X",5) -> 2
A30: T5_PC2 | B30: Quanto hai trovato facile pianificare una visita dalle informazioni sulle traduzioni disponibili? | F30: x | H30: =IF(C30="X",1)+IF(D30="X",2)+IF(E30="X",3)+IF(F30="X",4)+IF(G30="X",5) -> 4
B31: Motivation
A32: T5_MOT1 | B32: Come conoscere le curiosità di un sito nella tua lingua ti ha motivato visitarlo? | G32: x | H32: =IF(C32="X",1)+IF(D32="X",2)+IF(E32="X",3)+IF(F32="X",4)+IF(G32="X",5) -> 5
B33: Personal Control | C33: Scarso | D33: Sufficiente | E33: Buono | F33: Molto Buono | G33: Eccellente | H33: Valore
A34: T6_PC1 | B34: Quanto le tue conoscenze hanno influenzato la creazione di nuovi itinerari? | D34: x | H34: =IF(C34="X",1)+IF(D34="X",2)+IF(E34="X",3)+IF(F34="X",4)+IF(G34="X",5) -> 2
A35: T6_PC2 | B35: Quanto hai trovato facile informarsi sulle conoscenze necessarie alla creazione di nuovi itinerari? | D35: x | H35: =IF(C35="X",1)+IF(D35="X",2)+IF(E35="X",3)+IF(F35="X",4)+IF(G35="X",5) -> 2
B36: Motivation
A37: T6_MOT1 | B37: Quanto ha influenzato la pianificazione del tuo viaggio conoscere un particolare itinerario? | E37: x | H37: =IF(C37="X",1)+IF(D37="X",2)+IF(E37="X",3)+IF(F37="X",4)+IF(G37="X",5) -> 3
A38: T6_MOT2 | B38: Gli itinerari condivisi sono soddisfacenti? | C38: x | H38: =IF(C38="X",1)+IF(D38="X",2)+IF(E38="X",3)+IF(F38="X",4)+IF(G38="X",5) -> 1
B39: Motivation | C39: Scarso | D39: Sufficiente | E39: Buono | F39: Molto Buono | G39: Eccellente | H39: Valore
A40: T7_MOT1 | B40: I badge ottenuti dai diversi utenti, ti hanno motivato nella scelta di un determinato itinerario o di un determinato sito? | F40: x | H40: =IF(C40="X",1)+IF(D40="X",2)+IF(E40="X",3)+IF(F40="X",4)+IF(G40="X",5) -> 4
...

Sheet Questionario #5
B1: Self Efficacy | C1: Scarso | D1: Sufficiente | E1: Buono | F1: Molto Buono | G1: Eccellente | H1: Valore
A2: T1_SE1 | B2: In che modo hai consultato gli orari ufficiali del sito? | E2: x | H2: =IF(C2="X",1)+IF(D2="X",2)+IF(E2="X",3)+IF(F2="X",4)+IF(G2="X",5) -> 3
A3: T1_SE2 | B3: Quanto hai trovato facile reperire le informazioni sugli orari? | D3: x | H3: =IF(C3="X",1)+IF(D3="X",2)+IF(E3="X",3)+IF(F3="X",4)+IF(G3="X",5) -> 2
A4: T1_SE3 | B4: Le informazioni che hai trovato risultavano coerenti con gli orari effettivi del sito? | C4: x | H4: =IF(C4="X",1)+IF(D4="X",2)+IF(E4="X",3)+IF(F4="X",4)+IF(G4="X",5) -> 1
B5: Personal Control
A6: T1_PC1 | B6: In che modo riesci a pianificare, in maniera efficace e ottimizzando il tempo, il tuo viaggio consultando gli orari ufficiali? | C6: x | H6: =IF(C6="X",1)+IF(D6="X",2)+IF(E6="X",3)+IF(F6="X",4)+IF(G6="X",5) -> 1
A7: T1_PC2 | B7: Quanto hai trovato facile concordare l'orario di visita con l'orario di apertura del sito? | C7: x | H7: =IF(C7="X",1)+IF(D7="X",2)+IF(E7="X",3)+IF(F7="X",4)+IF(G7="X",5) -> 1
B8: Personal Control | C8: Scarso | D8: Sufficiente | E8: Buono | F8: Molto Buono | G8: Eccellente | H8: Valore
A9: T2_PC1 | B9: Quanto hai trovato facile reperire informazioni sulla disponibilità dei biglietti ed i loro prezzi? | C9: x | H9: =IF(C9="X",1)+IF(D9="X",2)+IF(E9="X",3)+IF(F9="X",4)+IF(G9="X",5) -> 1
A10: T2_PC2 | B10: In che modo sei riuscito a pianificare l'acquisto dei biglietti? | C10: x | H10: =IF(C10="X",1)+IF(D10="X",2)+IF(E10="X",3)+IF(F10="X",4)+IF(G10="X",5) -> 1
A11: T2_PC3 | B11: Quanto hai trovato facile capire se i biglietti per un determinato sito possono essere acquistati online? | D11: x | H11: =IF(C11="X",1)+IF(D11="X",2)+IF(E11="X",3)+IF(F11="X",4)+IF(G11="X",5) -> 2
B12: Self Efficacy | C12: Scarso | D12: Sufficiente | E12: Buono | F12: Molto Buono | G12: Eccellente | H12: Valore
A13: T3_SE1 | B13: In che modo sei riuscito a reperire le informazioni in maniera dettagliata? | D13: x | H13: =IF(C13="X",1)+IF(D13="X",2)+IF(E13="X",3)+IF(F13="X",4)+IF(G13="X",5) -> 2
A14: T3_SE2 | B14: In che modo hai trovato ciò che ti interessa? | E14: x | H14: =IF(C14="X",1)+IF(D14="X",2)+IF(E14="X",3)+IF(F14="X",4)+IF(G14="X",5) -> 3
A15: T3_SE3 | B15: Le informazioni fornite risultano essere... | D15: x | H15: =IF(C15="X",1)+IF(D15="X",2)+IF(E15="X",3)+IF(F15="X",4)+IF(G15="X",5) -> 2
B16: Self Efficacy | C16: Scarso | D16: Sufficiente | E16: Buono | F16: Molto Buono | G16: Eccellente | H16: Valore
A17: T4_SE1 | B17: Conoscere l'accessibilità del sito ti ha permesso di creare un itinerario migliore? Se si, come ti è sembrato? | D17: x | H17: =IF(C17="X",1)+IF(D17="X",2)+IF(E17="X",3)+IF(F17="X",4)+IF(G17="X",5) -> 2
A18: T4_SE2 | B18: Le informazioni sulle misure di accessibilità avvisano se il sito è visitabile da solo o è necessario/suggerito un accompagnatore? | E18: x | H18: =IF(C18="X",1)+IF(D18="X",2)+IF(E18="X",3)+IF(F18="X",4)+IF(G18="X",5) -> 3
B19: Knowledge&Skills
A20: T4_KS1 | B20: Le informazioni sulle misure di accessibilità sono sufficienti per chi è portatore di handicap? | F20: x | H20: =IF(C20="X",1)+IF(D20="X",2)+IF(E20="X",3)+IF(F20="X",4)+IF(G20="X",5) -> 4
A21: T4_KS2 | B21: Le informazioni sulle misure di accessibilità informano sul tipo di misure adottate e sui supporti disponibili? | C21: x | H21: =IF(C21="X",1)+IF(D21="X",2)+IF(E21="X",3)+IF(F21="X",4)+IF(G21="X",5) -> 1
B22: Personal Control
A23: T4_PC1 | B23: Le informazioni sulle misure di accessibilità al sito ha influenzato le tue decisioni? | E23: x | H23: =IF(C23="X",1)+IF(D23="X",2)+IF(E23="X",3)+IF(F23="X",4)+IF(G23="X",5) -> 3
A24: T4_PC2 | B24: Quanto hai trovato facile pianificare una visita dalle informazioni sulle misure di accessibilità trovate? | E24: x | H24: =IF(C24="X",1)+IF(D24="X",2)+IF(E24="X",3)+IF(F24="X",4)+IF(G24="X",5) -> 3
B25: Self Efficacy | C25: Scarso | D25: Sufficiente | E25: Buono | F25: Molto Buono | G25: Eccellente | H25: Valore
A26: T5_SE1 | B26: Quanto sono chiare le informazioni tradotte nella tua lingua? | F26: x | H26: =IF(C26="X",1)+IF(D26="X",2)+IF(E26="X",3)+IF(F26="X",4)+IF(G26="X",5) -> 4
A27: T5_SE2 | B27: Quanto sono complete le informazioni tradotte nella tua lingua? | F27: x | H27: =IF(C27="X",1)+IF(D27="X",2)+IF(E27="X",3)+IF(F27="X",4)+IF(G27="X",5) -> 4
B28: Personal Control
A29: T5_PC1 | B29: Le traduzioni disponibili hanno influenzato le tue decisioni? | E29: x | H29: =IF(C29="X",1)+IF(D29="X",2)+IF(E29="X",3)+IF(F29="X",4)+IF(G29="X",5) -> 3
A30: T5_PC2 | B30: Quanto hai trovato facile pianificare una visita dalle informazioni sulle traduzioni disponoibili? | F30: x | H30: =IF(C30="X",1)+IF(D30="X",2)+IF(E30="X",3)+IF(F30="X",4)+IF(G30="X",5) -> 4
B31: Motivation
A32: T5_MOT1 | B32: Come conoscere le curiosità di un sito nella tua lingua ti ha motivato visitarlo? | F32: x | H32: =IF(C32="X",1)+IF(D32="X",2)+IF(E32="X",3)+IF(F32="X",4)+IF(G32="X",5) -> 4
B33: Personal Control | C33: Scarso | D33: Sufficiente | E33: Buono | F33: Molto Buono | G33: Eccellente | H33: Valore
A34: T6_PC1 | B34: Quanto le tue conoscenze hanno influenzato la creazione di nuovi itinerari? | F34: x | H34: =IF(C34="X",1)+IF(D34="X",2)+IF(E34="X",3)+IF(F34="X",4)+IF(G34="X",5) -> 4
A35: T6_PC2 | B35: Quanto hai trovato facile informarsi sulle conoscenze necessarie alla creazione di nuovi itinerari? | F35: x | H35: =IF(C35="X",1)+IF(D35="X",2)+IF(E35="X",3)+IF(F35="X",4)+IF(G35="X",5) -> 4
B36: Motivation
A37: T6_MOT1 | B37: Quanto ha influenzato la pianificazione del tuo viaggio conoscere un particolare itinerario? | F37: x | H37: =IF(C37="X",1)+IF(D37="X",2)+IF(E37="X",3)+IF(F37="X",4)+IF(G37="X",5) -> 4
A38: T6_MOT2 | B38: Gli itinerari condivisi sono soddisfacenti? | E38: x | H38: =IF(C38="X",1)+IF(D38="X",2)+IF(E38="X",3)+IF(F38="X",4)+IF(G38="X",5) -> 3
B39: Motivation | C39: Scarso | D39: Sufficiente | E39: Buono | F39: Molto Buono | G39: Eccellente | H39: Valore
A40: T7_MOT1 | B40: I badge ottenuti dai diversi utenti, ti hanno motivato nella scelta di un determinato itinerario o di un determinato sito? | D40: x | H40: =IF(C40="X",1)+IF(D40="X",2)+IF(E40="X",3)+IF(F40="X",4)+IF(G40="X",5) -> 2
...
